Workbook

Sheet Dossards
A1: Dossard | B1: NOM | C1: PRENOM | D1: Sexe | E1: Naiss | F1: Club
A2: 1069 | B2: Abbadi | C2: Neil | D2: M | E2: 42911 | F2: USP | G2: 500
B3: ACQUART | C3: LILIAN | D3: M | E3: 42181 | F3: CAO
A4: 3099 | B4: Acremann | C4: Gabriel | D4: M | E4: 41307 | F4: USP | G4: 574
A5: 3080 | B5: ADOUE | C5: Théo | D5: M | E5: 41973 | F5: VAU | G5: 500
B6: AGUIAR | C6: Nuno | D6: M | E6: 42334 | F6: COU
B7: AKGUL-TERRIER | C7: Evan | D7: M | E7: 42370 | F7: USP
B8: AKGUL-TERRIER | C8: Matéo | D8: M | E8: 42005 | F8: USP
A9: 3041 | B9: ALAUME | C9: LOUISE | D9: F | E9: 41694 | F9: CAO | G9: 500
B10: ALAUZET | C10: LUCA | D10: M | E10: 41586 | F10: TTJ-BUC
A11: 4065 | B11: Alcide | C11: Ethan | D11: M | E11: 41032 | F11: USP | G11: 500
A12: 1070 | B12: ALINE | C12: Calie | D12: F | E12: 43191 | F12: API | G12: 500
A13: 1071 | B13: ALINE | C13: Milan | D13: M | E13: 44075 | F13: API | G13: 500
A14: 3073 | B14: ALVES | C14: Liam | D14: M | E14: 41339 | F14: COU | G14: 500
B15: AMIAUD | C15: Nils | D15: M | E15: 40909 | F15: USP
A16: 1063 | B16: AMMAR KHODJA | C16: Yanis | D16: M | E16: 42765 | F16: COU | G16: 500
A17: 1072 | B17: AMOURETTE | C17: Léo | D17: M | E17: 42775 | F17: API | G17: 500
A18: 3096 | B18: Andrieux | C18: Laora | D18: F | E18: 41620 | F18: USP | G18: 575
A19: 4063 | B19: Andrieux | C19: Leelouane | D19: F | E19: 40917 | F19: USP | G19: 500
A20: 1068 | B20: Andrieux | C20: Timéo | D20: M | E20: 43264 | F20: USP | G20: 508
B21: ANOKHIN | C21: Franck | D21: M | E21: 40909 | F21: USP
B22: ARCHAMBAUD | C22: Laura | D22: F | E22: 38929 | F22: CC2
B23: AREVALO | C23: Mathias | D23: M | E23: 39448 | F23: USP
B24: ARIS | C24: Amayas | D24: M | E24: 42103 | F24: CC2
B25: ARJOUNIN | C25: LIAM | D25: M | E25: 42258 | F25: COU
B26: ARJOUNIN | C26: NOAH | D26: M | E26: 41220 | F26: COU
A27: 2141 | B27: ARMAND | C27: Arthur | D27: M | E27: 42076 | F27: API | G27: 500
B28: ARTUS | C28: Clément | D28: M | E28: 40237 | F28: USP
A29: 2085 | B29: ASLAN | C29: Merwan | D29: M | E29: 42192 | F29: COU | G29: 500
B30: AUBERGER | C30: Julien | D30: M | E30: 39313 | F30: TTJ-BUC
A31: 2012 | B31: Aubert | C31: Lucie | D31: F | E31: 42666 | F31: TTJ-BUC | G31: 500
B32: AUBERT GUENIA | C32: Lucie | D32: F | E32: 42666 | F32: TTJ-BUC
B33: AUBRY | C33: GABRIEL | D33: M | E33: 41940 | F33: CAO
B34: AUDE | C34: Jules | D34: M | E34: 42629 | F34: TTJ-BUC
B35: AUDE | C35: Paul | D35: M | E35: 41744 | F35: TTJ-BUC
A36: 1073 | B36: AUDISIO | C36: Alexandre | D36: M | E36: 43245 | F36: API | G36: 500
A37: 2142 | B37: AUDISIO | C37: Julian | D37: M | E37: 42508 | F37: API | G37: 500
B38: AUGUSTE | C38: David | D38: M | E38: 41275 | F38: USP
B39: AUXOUX | C39: Sacha | D39: M | E39: 40989 | F39: TTJ-BUC
B40: AYADI | C40: Elyes | D40: M | E40: 42005 | F40: USP
...

Sheet Poussins
B1: TOURNOI DE LA VALLEE DE CHEVREUSE 2025-2026
B3: POUSSINS (-9)
C4: pour differencier vos joueurs | H4: Tour 1 | J4: Tour 2 | L4: Tour 3 | N4: Tour 4
C5: entrer votre code club : | E5: Tous | H5: 45991 | J5: 46040 | L5: 46103 | N5: 46180
A7: Dossard | B7: NOM | C7: PRENOM | D7: Sexe | E7: Naiss | F7: Club | G7: Class. | H7: Pr. T1 | I7: Points T1 | J7: Pr. T2 | K7: Points T2 | L7: Pr. T3 | M7: Points T3 | N7: Pr. T4 | O7: Points T4 | P7: TOTAL
A8: 1070 | B8: ALINE | C8: Calie | D8: F | E8: 43191 | F8: API | G8: 500 | P8: =SUM(I8:O8) -> 0
A9: 1071 | B9: ALINE | C9: Milan | D9: M | E9: 44075 | F9: API | G9: 500 | P9: =SUM(I9:O9) -> 0
A10: 1072 | B10: AMOURETTE | C10: Léo | D10: M | E10: 42775 | F10: API | G10: 500 | H10: x | I10: 1 | J10: x | P10: =SUM(I10:O10) -> 1
A11: 1073 | B11: AUDISIO | C11: Alexandre | D11: M | E11: 43245 | F11: API | G11: 500 | H11: x | I11: 6 | J11: x | P11: =SUM(I11:O11) -> 6
A12: 1074 | B12: CELMA CHAPOT | C12: Nattan | D12: M | E12: 43176 | F12: API | G12: 500 | H12: x | I12: 2 | J12: x | P12: =SUM(I12:O12) -> 2
A13: 1075 | B13: DELETRE | C13: Nessia | D13: F | E13: 42845 | F13: API | G13: 500 | P13: =SUM(I13:O13) -> 0
A14: 1076 | B14: EHLINGER | C14: Samuel | D14: M | E14: 44000 | F14: API | G14: 500 | P14: =SUM(I14:O14) -> 0
A15: 1077 | B15: FABRY | C15: Julian | D15: M | E15: 42997 | F15: API | G15: 500 | P15: =SUM(I15:O15) -> 0
A16: 1078 | B16: FRONTERA | C16: Enzo | D16: M | E16: 42927 | F16: API | G16: 501 | H16: x | I16: 7 | J16: x | P16: =SUM(I16:O16) -> 7
A17: 1079 | B17: GARIN | C17: Valentin | D17: M | E17: 43047 | F17: API | G17: 501 | H17: x | I17: 6 | J17: x | P17: =SUM(I17:O17) -> 6
A18: 1080 | B18: LAVILLE SANGRADO | C18: Ethan | D18: M | E18: 43110 | F18: API | G18: 500 | P18: =SUM(I18:O18) -> 0
A19: 1081 | B19: LEBAS | C19: Lucie | D19: F | E19: 43081 | F19: API | G19: 500 | P19: =SUM(I19:O19) -> 0
A20: 1082 | B20: MOISSANT MAUDUIT | C20: Noah | D20: M | E20: 43882 | F20: API | G20: 500 | P20: =SUM(I20:O20) -> 0
A21: 1083 | B21: NOUR LOUIS | C21: Lucas | D21: M | E21: 42961 | F21: API | G21: 500 | H21: x | I21: 6 | J21: x | P21: =SUM(I21:O21) -> 6
A22: 1084 | B22: ROUE | C22: Charles | D22: M | E22: 43371 | F22: API | G22: 500 | P22: =SUM(I22:O22) -> 0
A23: 1085 | B23: SCHMITT | C23: Loan | D23: M | E23: 43268 | F23: API | G23: 500 | P23: =SUM(I23:O23) -> 0
A24: 1086 | B24: SISMEIRO | C24: Lucas | D24: M | E24: 42820 | F24: API | G24: 501 | H24: x | I24: 8 | J24: x | P24: =SUM(I24:O24) -> 8
A25: 1087 | B25: SURMON | C25: Charlie | D25: M | E25: 43406 | F25: API | G25: 500 | H25: x | I25: 6 | J25: x | P25: =SUM(I25:O25) -> 6
A26: 1088 | B26: THIERY | C26: Clément | D26: M | E26: 43180 | F26: API | G26: 500 | H26: x | I26: 4 | J26: x | P26: =SUM(I26:O26) -> 4
A27: 1050 | B27: BENHAMOU | C27: Ilan | D27: M | E27: 42883 | F27: ASV | G27: 500 | P27: =SUM(I27:O27) -> 0
A28: 1018 | B28: DELAYE MOCQUARD | C28: Evangeline | D28: F | E28: 43293 | F28: ASV | G28: 500 | H28: x | I28: 3 | J28: x | P28: =SUM(I28:O28) -> 3
A29: 1019 | B29: DELAYE MOCQUARD | C29: Joscelin | D29: M | E29: 43293 | F29: ASV | G29: 500 | H29: x | I29: 1 | J29: x | P29: =SUM(I29:O29) -> 1
A30: 1043 | B30: EHONGO | C30: Lorenzo | D30: M | E30: 43035 | F30: ASV | G30: 500 | P30: =SUM(I30:O30) -> 0
A31: 1030 | B31: FALINOWER | C31: Saël | D31: M | E31: 43154 | F31: ASV | G31: 500 | H31: x | I31: 6 | J31: x | P31: =SUM(I31:O31) -> 6
A32: 1012 | B32: PEREIRA | C32: Léandre | D32: M | E32: 43425 | F32: ASV | G32: 500 | P32: =SUM(I32:O32) -> 0
A33: 1060 | B33: RASKIN | C33: Sohan | D33: M | E33: 42802 | F33: ASV | G33: 500 | H33: x | I33: 6 | J33: x | P33: =SUM(I33:O33) -> 6
A34: 1020 | B34: VIDAL | C34: Nathan | D34: M | E34: 43290 | F34: ASV | G34: 500 | P34: =SUM(I34:O34) -> 0
A35: 1013 | B35: BEUVELET | C35: BENJAMIN | D35: M | E35: 43410 | F35: CAO | G35: 500 | P35: =SUM(I35:O35) -> 0
A36: 1057 | B36: GRANDIDIER | C36: VICTOR | D36: M | E36: 42825 | F36: CAO | G36: 503 | H36: x | I36: 9 | J36: x | P36: =SUM(I36:O36) -> 9
A37: 1058 | B37: LANDRAGIN | C37: AMELIE | D37: F | E37: 42820 | F37: CAO | G37: 500 | P37: =SUM(I37:O37) -> 0
A38: 1011 | B38: LOPEZ VARGAS | C38: BRUNO | D38: M | E38: 43438 | F38: CAO | G38: 500 | P38: =SUM(I38:O38) -> 0
A39: 1021 | B39: NGUYEN | C39: JULIEN | D39: M | E39: 43236 | F39: CAO | G39: 500 | P39: =SUM(I39:O39) -> 0
A40: 1024 | B40: YVART | C40: CONSTANT | D40: M | E40: 43231 | F40: CAO | G40: 500 | P40: =SUM(I40:O40) -> 0
A41: 1028 | B41: AYRAULT | C41: Mathéïs | D41: M | E41: 43182 | F41: CC2 | G41: 500 | H41: x | I41: 2 | J41: x | P41: =SUM(I41:O41) -> 2
A42: 1023 | B42: BANU | C42: Luca | D42: M | E42: 43232 | F42: CC2 | G42: 500 | P42: =SUM(I42:O42) -> 0
...

Sheet Benjamins
B1: =Poussins!B1 -> TOURNOI DE LA VALLEE DE CHEVREUSE 2025-2026
B3: BENJAMINS (-11)
C4: pour differencier vos joueurs | H4: Tour 1 | J4: Tour 2 | L4: Tour 3 | N4: Tour 4
C5: entrer votre code club : | E5: Tous | H5: =Poussins!H5 -> 45991 | J5: =Poussins!J5 -> 46040 | L5: =Poussins!L5 -> 46103 | N5: =Poussins!N5 -> 46180
A7: Dossard | B7: NOM | C7: PRENOM | D7: Sexe | E7: Naiss | F7: Club | G7: Class. | H7: Pr. T1 | I7: Points T1 | J7: Pr. T2 | K7: Points T2 | L7: Pr. T3 | M7: Points T3 | N7: Pr. T4 | O7: Points T4 | P7: TOTAL
A8: 2141 | B8: ARMAND | C8: Arthur | D8: M | E8: 42076 | F8: API | G8: 500 | P8: =SUM(I8:O8) -> 0
A9: 2142 | B9: AUDISIO | C9: Julian | D9: M | E9: 42508 | F9: API | G9: 500 | H9: X | I9: 9 | J9: X | P9: =SUM(I9:O9) -> 9
A10: 2143 | B10: BELHOUARI | C10: Sami | D10: M | E10: 42407 | F10: API | G10: 500 | H10: X | I10: 8 | J10: X | P10: =SUM(I10:O10) -> 8
A11: 2144 | B11: BENTEGHEROUIT | C11: Adam | D11: M | E11: 42326 | F11: API | G11: 500 | P11: =SUM(I11:O11) -> 0
A12: 2145 | B12: BRAULT | C12: Auxane | D12: F | E12: 42096 | F12: API | G12: 500 | P12: =SUM(I12:O12) -> 0
A13: 2146 | B13: BUGUET | C13: Adryan | D13: M | E13: 42265 | F13: API | G13: 500 | P13: =SUM(I13:O13) -> 0
A14: 2147 | B14: CARDON | C14: Antoine | D14: M | E14: 42014 | F14: API | G14: 500 | H14: X | I14: 10 | J14: X | P14: =SUM(I14:O14) -> 10
A15: 2148 | B15: CORTES | C15: Rafael | D15: M | E15: 42637 | F15: API | G15: 500 | H15: X | I15: 8 | J15: X | P15: =SUM(I15:O15) -> 8
A16: 2149 | B16: COUFFIGNAL | C16: Romain | D16: M | E16: 42130 | F16: API | G16: 500 | P16: =SUM(I16:O16) -> 0
A17: 2150 | B17: COURBIN | C17: Armand | D17: M | E17: 42390 | F17: API | G17: 500 | H17: X | I17: 8 | J17: X | P17: =SUM(I17:O17) -> 8
A18: 2151 | B18: DEJONC | C18: Adam | D18: M | E18: 42419 | F18: API | G18: 500 | H18: X | I18: 8 | J18: X | P18: =SUM(I18:O18) -> 8
A19: 2152 | B19: DELTHEIL | C19: Gauvin | D19: M | E19: 42178 | F19: API | G19: 500 | H19: X | I19: 4 | J19: X | P19: =SUM(I19:O19) -> 4
A20: 2153 | B20: DELTHEIL | C20: Ombeline | D20: F | E20: 42185 | F20: API | G20: 500 | H20: X | I20: 1 | J20: X | P20: =SUM(I20:O20) -> 1
A21: 2154 | B21: DOKHAN | C21: Samuel | D21: M | E21: 42600 | F21: API | G21: 500 | P21: =SUM(I21:O21) -> 0
A22: 2156 | B22: DOUBLET DECABRAS | C22: Antoine | D22: M | E22: 42669 | F22: API | G22: 500 | H22: X | I22: 3 | J22: X | P22: =SUM(I22:O22) -> 3
A23: 2155 | B23: DOUBLET DECABRAS | C23: Pierre | D23: M | E23: 42669 | F23: API | G23: 500 | H23: X | I23: 8 | J23: X | P23: =SUM(I23:O23) -> 8
A24: 2157 | B24: DUVAL | C24: Alessio | D24: M | E24: 42483 | F24: API | G24: 500 | H24: X | I24: 3 | J24: X | P24: =SUM(I24:O24) -> 3
A25: 2158 | B25: FELLOUS | C25: Jonah | D25: M | E25: 42066 | F25: API | G25: 500 | P25: =SUM(I25:O25) -> 0
A26: 2159 | B26: FLAMENT | C26: Corentin | D26: M | E26: 42484 | F26: API | G26: 500 | H26: X | I26: 3 | J26: X | P26: =SUM(I26:O26) -> 3
A27: 2160 | B27: FRANCOIS | C27: Arthur | D27: M | E27: 42055 | F27: API | G27: 500 | H27: X | I27: 9 | J27: X | P27: =SUM(I27:O27) -> 9
A28: 2161 | B28: GENDRON CARALP | C28: Léo | D28: M | E28: 42574 | F28: API | G28: 500 | H28: X | I28: 8 | J28: X | P28: =SUM(I28:O28) -> 8
A29: 2162 | B29: JACOBERGER | C29: Ethan | D29: M | E29: 42066 | F29: API | G29: 500 | H29: X | I29: 9 | J29: X | P29: =SUM(I29:O29) -> 9
A30: 2163 | B30: LACROIX MARTIN | C30: Adam | D30: M | E30: 42088 | F30: API | G30: 500 | H30: X | I30: 9 | J30: X | P30: =SUM(I30:O30) -> 9
A31: 2164 | B31: LE BELLEC | C31: Martin | D31: M | E31: 42281 | F31: API | G31: 500 | P31: =SUM(I31:O31) -> 0
A32: 2165 | B32: LEBERT | C32: Arthur | D32: M | E32: 42526 | F32: API | G32: 501 | H32: x | I32: 11 | J32: x | P32: =SUM(I32:O32) -> 11
A33: 2166 | B33: LEBERT | C33: Raphael | D33: M | E33: 42526 | F33: API | G33: 548 | H33: x | I33: 15 | J33: x | P33: =SUM(I33:O33) -> 15
A34: 2167 | B34: LEONARD | C34: Paul | D34: M | E34: 42158 | F34: API | G34: 500 | P34: =SUM(I34:O34) -> 0
A35: 2168 | B35: MAILLAUD | C35: Merlin | D35: M | E35: 42449 | F35: API | G35: 500 | H35: X | I35: 11 | J35: X | P35: =SUM(I35:O35) -> 11
A36: 2169 | B36: MORIN SUISSE | C36: George | D36: M | E36: 42268 | F36: API | G36: 500 | H36: X | I36: 2 | J36: X | P36: =SUM(I36:O36) -> 2
A37: 2170 | B37: MZIOU | C37: Skander | D37: M | E37: 42583 | F37: API | G37: 500 | H37: X | I37: 2 | J37: X | P37: =SUM(I37:O37) -> 2
A38: 2171 | B38: N'SONGAN | C38: Lya | D38: F | E38: 42697 | F38: API | G38: 500 | P38: =SUM(I38:O38) -> 0
A39: 2172 | B39: REFAIT | C39: Lucas | D39: M | E39: 42256 | F39: API | G39: 500 | P39: =SUM(I39:O39) -> 0
A40: 2173 | B40: RENAUX | C40: Alix | D40: M | E40: 42087 | F40: API | G40: 500 | H40: x | I40: 1 | J40: x | P40: =SUM(I40:O40) -> 1
A41: 2174 | B41: ROSSI JURBERT | C41: Noelie | D41: F | E41: 42288 | F41: API | G41: 500 | H41: X | I41: 10 | J41: X | P41: =SUM(I41:O41) -> 10
A42: 2175 | B42: SUZANO | C42: Maxime | D42: M | E42: 42408 | F42: API | G42: 500 | P42: =SUM(I42:O42) -> 0
...

Sheet Minimes
B1: =Poussins!B1 -> TOURNOI DE LA VALLEE DE CHEVREUSE 2025-2026
B3: MINIMES (-13)
C4: pour differencier vos joueurs | H4: Tour 1 | J4: Tour 2 | L4: Tour 3 | N4: Tour 4
C5: entrer votre code club : | E5: Tout | H5: =Poussins!H5 -> 45991 | J5: =Poussins!J5 -> 46040 | L5: =Poussins!L5 -> 46103 | N5: =Poussins!N5 -> 46180
A7: Dossard | B7: NOM | C7: PRENOM | D7: Sexe | E7: Naiss | F7: Club | G7: Class. | H7: Pr. T1 | I7: Points T1 | J7: Pr. T2 | K7: Points T2 | L7: Pr. T3 | M7: Points T3 | N7: Pr. T4 | O7: Points T4 | P7: TOTAL
A8: 3100 | B8: BRANLE | C8: Benjamin | D8: M | E8: 41694 | F8: API | G8: 500 | P8: =SUM(I8:O8) -> 0
A9: 3101 | B9: BRUGEILLES | C9: Noé | D9: M | E9: 41757 | F9: API | G9: 500 | P9: =SUM(I9:O9) -> 0
A10: 3102 | B10: CATHERIN | C10: Alice | D10: F | E10: 41563 | F10: API | G10: 737 | P10: =SUM(I10:O10) -> 0
A11: 3103 | B11: CATHERIN | C11: Julie | D11: F | E11: 41563 | F11: API | G11: 697 | P11: =SUM(I11:O11) -> 0
A12: 3104 | B12: DECODTS | C12: Amaury | D12: M | E12: 41465 | F12: API | G12: 500 | P12: =SUM(I12:O12) -> 0
A13: 3105 | B13: DESPRIN | C13: Gaetan | D13: M | E13: 41657 | F13: API | G13: 660 | H13: x | I13: 10 | P13: =SUM(I13:O13) -> 10
A14: 3106 | B14: FERNANDES | C14: Eva | D14: F | E14: 41787 | F14: API | G14: 500 | P14: =SUM(I14:O14) -> 0
A15: 3107 | B15: FLAMENT | C15: Emilien | D15: M | E15: 41700 | F15: API | G15: 525 | H15: x | I15: 7 | P15: =SUM(I15:O15) -> 7
A16: 3108 | B16: GAILLY DAUGAS | C16: Quentin | D16: M | E16: 41507 | F16: API | G16: 500 | P16: =SUM(I16:O16) -> 0
A17: 3109 | B17: GARCIA | C17: Simon | D17: M | E17: 41412 | F17: API | G17: 1456 | P17: =SUM(I17:O17) -> 0
A18: 3110 | B18: GOUDEY | C18: Aymeric | D18: M | E18: 41798 | F18: API | G18: 851 | P18: =SUM(I18:O18) -> 0
A19: 3111 | B19: HAIBOU | C19: Darren | D19: M | E19: 41602 | F19: API | G19: 500 | P19: =SUM(I19:O19) -> 0
A20: 3112 | B20: HALPERN | C20: Ciaran | D20: M | E20: 41454 | F20: API | G20: 500 | P20: =SUM(I20:O20) -> 0
A21: 3113 | B21: JOLY | C21: Raphael | D21: M | E21: 41476 | F21: API | G21: 500 | P21: =SUM(I21:O21) -> 0
A22: 3114 | B22: LEBERT | C22: Elliot | D22: M | E22: 41730 | F22: API | G22: 576 | P22: =SUM(I22:O22) -> 0
A23: 3115 | B23: LEGARSON | C23: Valentin | D23: M | E23: 41800 | F23: API | G23: 815 | P23: =SUM(I23:O23) -> 0
A24: 3116 | B24: LEGENDRE | C24: Ben | D24: M | E24: 41963 | F24: API | G24: 500 | P24: =SUM(I24:O24) -> 0
A25: 3117 | B25: LEMAITRE | C25: Eden | D25: M | E25: 41983 | F25: API | G25: 500 | P25: =SUM(I25:O25) -> 0
A26: 3118 | B26: LINARD | C26: Julien | D26: M | E26: 41435 | F26: API | G26: 500 | P26: =SUM(I26:O26) -> 0
A27: 3119 | B27: MARQUES | C27: Fanny | D27: F | E27: 41529 | F27: API | G27: 500 | H27: x | I27: 1 | P27: =SUM(I27:O27) -> 1
A28: 3120 | B28: MELKA | C28: Diego | D28: M | E28: 41431 | F28: API | G28: 500 | P28: =SUM(I28:O28) -> 0
A29: 3121 | B29: PERONNE | C29: Aymeric | D29: M | E29: 41745 | F29: API | G29: 715 | H29: x | I29: 11 | P29: =SUM(I29:O29) -> 11
A30: 3122 | B30: RUHLMANN | C30: Thomas | D30: M | E30: 41375 | F30: API | G30: 512 | P30: =SUM(I30:O30) -> 0
A31: 3123 | B31: SEGRESTAN | C31: Tiago | D31: M | E31: 41509 | F31: API | G31: 500 | P31: =SUM(I31:O31) -> 0
A32: 3124 | B32: SISMEIRO | C32: Célia | D32: F | E32: 41809 | F32: API | G32: 500 | P32: =SUM(I32:O32) -> 0
A33: 3125 | B33: TRICOT | C33: Adrien | D33: M | E33: 41967 | F33: API | G33: 617 | H33: x | I33: 9 | P33: =SUM(I33:O33) -> 9
A34: 3126 | B34: VELLUET | C34: Auxence | D34: M | E34: 41975 | F34: API | G34: 636 | H34: x | I34: 9 | P34: =SUM(I34:O34) -> 9
A35: 3127 | B35: VERGNAUD | C35: Louis | D35: M | E35: 41696 | F35: API | G35: 500 | H35: x | I35: 1 | P35: =SUM(I35:O35) -> 1
A36: 3128 | B36: YANG | C36: Franz | D36: M | E36: 41678 | F36: API | G36: 500 | P36: =SUM(I36:O36) -> 0
A37: 3130 | B37: GUILLEMET | C37: Lohann | D37: M | E37: 41640 | F37: ASM | G37: 500 | P37: =SUM(I37:O37) -> 0
A38: 3131 | B38: minime Marcoussis | C38: ? | D38: M | E38: 41640 | F38: ASM | G38: 500 | P38: =SUM(I38:O38) -> 0
A39: 3037 | B39: CHEN | C39: Iris-Xiya | D39: F | E39: 41718 | F39: ASV | G39: 500 | H39: x | I39: 7 | P39: =SUM(I39:O39) -> 7
A40: 3077 | B40: GOUJON | C40: Alexandre | D40: M | E40: 41292 | F40: ASV | G40: 500 | P40: =SUM(I40:O40) -> 0
A41: 3053 | B41: TIAO | C41: Ethan | D41: M | E41: 41540 | F41: ASV | G41: 500 | P41: =SUM(I41:O41) -> 0
A42: 3041 | B42: ALAUME | C42: LOUISE | D42: F | E42: 41694 | F42: CAO | G42: 500 | H42: x | I42: 1 | P42: =SUM(I42:O42) -> 1
...

Sheet Cadets-Juniors
B1: =Poussins!B1 -> TOURNOI DE LA VALLEE DE CHEVREUSE 2025-2026
B3: CADETS-JUNIORS (-15 et -18)
C4: pour differencier vos joueurs | H4: Tour 1 | J4: Tour 2 | L4: Tour 3 | N4: Tour 4
C5: entrer votre code club : | E5: Tout | H5: =Poussins!H5 -> 45991 | J5: =Poussins!J5 -> 46040 | L5: =Poussins!L5 -> 46103 | N5: =Poussins!N5 -> 46180
A7: Dossard | B7: NOM | C7: PRENOM | D7: Sexe | E7: Naiss | F7: Club | G7: Class. | H7: Pr. T1 | I7: Points T1 | J7: Pr. T2 | K7: Points T2 | L7: Pr. T3 | M7: Points T3 | N7: Pr. T4 | O7: Points T4 | P7: TOTAL
A8: 4070 | B8: BELLIL NASCIET | C8: Nora | D8: F | E8: 41002 | F8: API | G8: 500 | P8: =SUM(I8:O8) -> 0
A9: 4071 | B9: CAUSSE | C9: Axel | D9: M | E9: 41263 | F9: API | G9: 500 | H9: x | I9: 7 | P9: =SUM(I9:O9) -> 7
A10: 4072 | B10: CORDE | C10: Jules | D10: M | E10: 40870 | F10: API | G10: 1134 | P10: =SUM(I10:O10) -> 0
A11: 4083 | B11: CORTES | C11: Nathan | D11: M | E11: 40269 | F11: API | G11: 500 | P11: =SUM(I11:O11) -> 0
A12: 4073 | B12: DESPRIN | C12: Lya | D12: F | E12: 40922 | F12: API | G12: 500 | P12: =SUM(I12:O12) -> 0
A13: 4074 | B13: GAJECKI | C13: Justin | D13: M | E13: 41104 | F13: API | G13: 940 | P13: =SUM(I13:O13) -> 0
A14: 4075 | B14: GALTIER | C14: Ethan | D14: M | E14: 41123 | F14: API | G14: 500 | P14: =SUM(I14:O14) -> 0
A15: 4084 | B15: GENIAUT | C15: Rémi | D15: M | E15: 40165 | F15: API | G15: 500 | P15: =SUM(I15:O15) -> 0
A16: 4076 | B16: GIRAUD | C16: Jules | D16: M | E16: 40694 | F16: API | G16: 500 | P16: =SUM(I16:O16) -> 0
A17: 4085 | B17: GOUDEY | C17: Aurélien | D17: M | E17: 40485 | F17: API | G17: 983 | P17: =SUM(I17:O17) -> 0
A18: 4077 | B18: HLAVACEK | C18: Oscar | D18: M | E18: 40932 | F18: API | G18: 1036 | P18: =SUM(I18:O18) -> 0
A19: 4078 | B19: HLAVACEK | C19: Timothée | D19: M | E19: 40932 | F19: API | G19: 726 | P19: =SUM(I19:O19) -> 0
A20: 4086 | B20: IACOUCCI | C20: Benjamin | D20: M | E20: 39194 | F20: API | G20: 1054 | P20: =SUM(I20:O20) -> 0
A21: 4079 | B21: LACAZE | C21: Adrien | D21: M | E21: 41258 | F21: API | G21: 840 | P21: =SUM(I21:O21) -> 0
... A25: 4081 | B25: MANCELLE HIMIDI | C25: Inaya | D25: F | E25: 41135 | F25: API | G25: 785 | P25: =SUM(I25:O25) -> 0
A26: 4089 | B26: MICHEL | C26: Paul | D26: M | E26: 40048 | F26: API | G26: 610 | H26: x | I26: 8 | P26: =SUM(I26:O26) -> 8
A27: 4082 | B27: REFAIT | C27: Lilian | D27: M | E27: 40909 | F27: API | G27: 500 | P27: =SUM(I27:O27) -> 0
A28: 4090 | B28: ROSSI JURBERT | C28: Corentin | D28: M | E28: 39896 | F28: API | G28: 1146 | H28: x | I28: 13 | P28: =SUM(I28:O28) -> 13
A29: 4091 | B29: ROYER VARNAT | C29: Landry | D29: M | E29: 40207 | F29: API | G29: 967 | P29: =SUM(I29:O29) -> 0
A30: 4092 | B30: VIALLET | C30: Mathéo | D30: M | E30: 40501 | F30: API | G30: 500 | P30: =SUM(I30:O30) -> 0
A31: 4095 | B31: BAUDOU | C31: Ilyan | D31: M | E31: 40909 | F31: ASM | G31: 500 | H31: x | I31: 2 | P31: =SUM(I31:O31) -> 2
A32: 4093 | B32: PIGENET | C32: Raphaël | D32: M | E32: 40544 | F32: ASM | G32: 500 | H32: x | I32: 8 | P32: =SUM(I32:O32) -> 8
A33: 4096 | B33: MERCUZOT KEIZER | C33: Alban | D33: M | E33: 40544 | F33: ASM | G33: 500 | H33: x | I33: 1 | P33: =SUM(I33:O33) -> 1
A34: 4094 | B34: THEZE | C34: Axel | D34: M | E34: 40544 | F34: ASM | G34: 500 | H34: x | I34: 3 | P34: =SUM(I34:O34) -> 3
A35: 4019 | B35: PESCHEUX-URRUTIA | C35: Sacha | D35: M | E35: 40958 | F35: ASV | G35: 822 | P35: =SUM(I35:O35) -> 0
A36: 4017 | B36: TEOFILO | C36: Gabriel | D36: M | E36: 40991 | F36: ASV | G36: 500 | H36: x | I36: 3 | P36: =SUM(I36:O36) -> 3
A37: 4012 | B37: VOISIN | C37: Isaac | D37: M | E37: 41158 | F37: ASV | G37: 500 | H37: x | I37: 1 | P37: =SUM(I37:O37) -> 1
A38: 4024 | B38: BALIGAND | C38: CORENTIN | D38: M | E38: 40861 | F38: CAO | G38: 647 | H38: x | I38: 8 | P38: =SUM(I38:O38) -> 8
A39: 4032 | B39: CAILLERIE | C39: MARIE | D39: F | E39: 40711 | F39: CAO | G39: 500 | P39: =SUM(I39:O39) -> 0
A40: 4021 | B40: CANARD | C40: LAURA | D40: F | E40: 40897 | F40: CAO | G40: 500 | P40: =SUM(I40:O40) -> 0
A41: 4018 | B41: GEISEN | C41: JEREMIE | D41: M | E41: 40958 | F41: CAO | G41: 500 | P41: =SUM(I41:O41) -> 0
A42: 4020 | B42: LARONZE | C42: TRISTAN | D42: M | E42: 40905 | F42: CAO | G42: 500 | P42: =SUM(I42:O42) -> 0
A43: 4009 | B43: LAVERRE | C43: ARTHUR | D43: M | E43: 41185 | F43: CAO | G43: 500 | P43: =SUM(I43:O43) -> 0
A44: 4013 | B44: LEROY | C44: ABEL | D44: M | E44: 41157 | F44: CAO | G44: 619 | H44: x | I44: 7 | P44: =SUM(I44:O44) -> 7
A45: 4043 | B45: MIREBEAU | C45: NATHANAËL | D45: M | E45: 40428 | F45: CAO | G45: 500 | P45: =SUM(I45:O45) -> 0
...

Sheet Feminines
B1: =Poussins!B1 -> TOURNOI DE LA VALLEE DE CHEVREUSE 2025-2026
B3: FEMININES (toutes catégories)
C4: pour differencier vos joueurs | H4: Tour 1 | J4: Tour 2 | L4: Tour 3 | N4: Tour 4
C5: entrer votre code club : | E5: Tout | H5: =Poussins!H5 -> 45991 | J5: =Poussins!J5 -> 46040 | L5: =Poussins!L5 -> 46103 | N5: =Poussins!N5 -> 46180
A7: Dossard | B7: NOM | C7: PRENOM | D7: Sexe | E7: Naiss | F7: Club | G7: Class. | H7: Pr. T1 | I7: Points T1 | J7: Pr. T2 | K7: Points T2 | L7: Pr. T3 | M7: Points T3 | N7: Pr. T4 | O7: Points T4 | P7: TOTAL
A8: 1070 | B8: ALINE | C8: Calie | D8: F | E8: 43191 | F8: API | G8: 500 | P8: =SUM(I8:O8) -> 0
A9: 4070 | B9: BELLIL NASCIET | C9: Nora | D9: F | E9: 41002 | F9: API | G9: 500 | P9: =SUM(I9:O9) -> 0
A10: 2145 | B10: BRAULT | C10: Auxane | D10: F | E10: 42096 | F10: API | G10: 678 | P10: =SUM(I10:O10) -> 0
A11: 3102 | B11: CATHERIN | C11: Alice | D11: F | E11: 41563 | F11: API | G11: 737 | P11: =SUM(I11:O11) -> 0
A12: 3103 | B12: CATHERIN | C12: Julie | D12: F | E12: 41563 | F12: API | G12: 697 | P12: =SUM(I12:O12) -> 0
A13: 1075 | B13: DELETRE | C13: Nessia | D13: F | E13: 42845 | F13: API | G13: 500 | P13: =SUM(I13:O13) -> 0
A14: 2153 | B14: DELTHEIL | C14: Ombeline | D14: F | E14: 42185 | F14: API | G14: 500 | P14: =SUM(I14:O14) -> 0
A15: 4073 | B15: DESPRIN | C15: Lya | D15: F | E15: 40922 | F15: API | G15: 500 | P15: =SUM(I15:O15) -> 0
A16: 3106 | B16: FERNANDES | C16: Eva | D16: F | E16: 41787 | F16: API | G16: 500 | P16: =SUM(I16:O16) -> 0
A17: 4087 | B17: LEBAS | C17: Emma | D17: F | E17: 39874 | F17: API | G17: 500 | P17: =SUM(I17:O17) -> 0
A18: 1081 | B18: LEBAS | C18: Lucie | D18: F | E18: 43081 | F18: API | G18: 500 | P18: =SUM(I18:O18) -> 0
A19: 4081 | B19: MANCELLE HIMIDI | C19: Inaya | D19: F | E19: 41135 | F19: API | G19: 785 | P19: =SUM(I19:O19) -> 0
A20: 3119 | B20: MARQUES | C20: Fanny | D20: F | E20: 41529 | F20: API | G20: 500 | H20: x | I20: 7 | P20: =SUM(I20:O20) -> 7
A21: 2171 | B21: N'SONGAN | C21: Lya | D21: F | E21: 42697 | F21: API | G21: 500 | P21: =SUM(I21:O21) -> 0
A22: 2174 | B22: ROSSI JURBERT | C22: Noelie | D22: F | E22: 42288 | F22: API | G22: 500 | H22: x | I22: 5 | P22: =SUM(I22:O22) -> 5
A23: 3124 | B23: SISMEIRO | C23: Célia | D23: F | E23: 41809 | F23: API | G23: 500 | P23: =SUM(I23:O23) -> 0
A24: 2177 | B24: ZENIA | C24: Karen | D24: F | E24: 42406 | F24: API | G24: 500 | P24: =SUM(I24:O24) -> 0
F25: ASM | P25: =SUM(I25:O25) -> 0
A26: 3037 | B26: CHEN | C26: Iris-Xiya | D26: F | E26: 41718 | F26: ASV | G26: 500 | H26: x | I26: 5 | P26: =SUM(I26:O26) -> 5
A27: 1018 | B27: DELAYE MOCQUARD | C27: Evangeline | D27: F | E27: 43293 | F27: ASV | G27: 500 | P27: =SUM(I27:O27) -> 0
A28: 3041 | B28: ALAUME | C28: LOUISE | D28: F | E28: 41694 | F28: CAO | G28: 500 | H28: x | I28: 2 | P28: =SUM(I28:O28) -> 2
A29: 4032 | B29: CAILLERIE | C29: MARIE | D29: F | E29: 40711 | F29: CAO | G29: 500 | P29: =SUM(I29:O29) -> 0
A30: 4021 | B30: CANARD | C30: LAURA | D30: F | E30: 40897 | F30: CAO | G30: 500 | P30: =SUM(I30:O30) -> 0
A31: 2101 | B31: FOURMY | C31: ALIX | D31: F | E31: 42069 | F31: CAO | G31: 500 | P31: =SUM(I31:O31) -> 0
A32: 3003 | B32: GIRAUD | C32: ADELE | D32: F | E32: 41984 | F32: CAO | G32: 500 | P32: =SUM(I32:O32) -> 0
A33: 1058 | B33: LANDRAGIN | C33: AMELIE | D33: F | E33: 42820 | F33: CAO | G33: 500 | P33: =SUM(I33:O33) -> 0
A34: 4025 | B34: WILLEKENS SERVY | C34: LIVIA | D34: F | E34: 40861 | F34: CAO | G34: 500 | P34: =SUM(I34:O34) -> 0
A35: 1000 | B35: BESSON DRUI | C35: Salomé | D35: F | E35: 44506 | F35: CC2 | G35: 500 | P35: =SUM(I35:O35) -> 0
A36: 4001 | B36: BIÉLANDE | C36: Emmy | D36: F | E36: 41272 | F36: CC2 | G36: 500 | H36: x | I36: 6 | P36: =SUM(I36:O36) -> 6
A37: 2050 | B37: GLEMET | C37: Lauryn | D37: F | E37: 42384 | F37: CC2 | G37: 500 | P37: =SUM(I37:O37) -> 0
A38: 1006 | B38: GROSJEAN | C38: Jade | D38: F | E38: 43694 | F38: CC2 | G38: 500 | P38: =SUM(I38:O38) -> 0
A39: 4011 | B39: ISENBERG | C39: Franziska | D39: F | E39: 41161 | F39: CC2 | G39: 500 | P39: =SUM(I39:O39) -> 0
A40: 1003 | B40: LALEU | C40: Alicia | D40: F | E40: 43962 | F40: CC2 | G40: 500 | P40: =SUM(I40:O40) -> 0
A41: 3029 | B41: PETIT | C41: Lilou | D41: F | E41: 41772 | F41: CC2 | G41: 500 | P41: =SUM(I41:O41) -> 0
A42: 1008 | B42: RETHO | C42: Lucie | D42: F | E42: 43645 | F42: CC2 | G42: 500 | P42: =SUM(I42:O42) -> 0
...

Sheet LISTTOUS
A1: Dossard | B1: NOM | C1: PRENOM | D1: Sexe | E1: Naiss | F1: Club
A2: 1000 | B2: ABBADI | C2: Neil | D2: M | E2: 42911 | F2: USP
A3: 2000 | B3: ACQUART | C3: LILIAN | D3: M | E3: 42181 | F3: CAO
A4: 3000 | B4: ACREMANN | C4: Gabriel | D4: M | E4: 2013 | F4: USP
A5: 2001 | B5: ADOUE | C5: Théo | D5: M | E5: 41973 | F5: VAU
A6: 2002 | B6: AGUIAR | C6: Nuno | D6: M | E6: 42334 | F6: COU
A7: 1001 | B7: AKGUL-TERRIER | C7: Evan | D7: M | E7: 2016 | F7: USP
A8: 2003 | B8: AKGUL-TERRIER | C8: Matéo | D8: M | E8: 2015 | F8: USP
A9: 2004 | B9: ALAUME | C9: LOUISE | D9: F | E9: 41694 | F9: CAO
A10: 3001 | B10: ALAUZET | C10: LUCA | D10: M | E10: 41586 | F10: TTJ-BUC
A11: 1002 | B11: ALINE | C11: Calie | D11: F | E11: 43191 | F11: API
A12: 1003 | B12: ALINE | C12: Milan | D12: M | E12: 44075 | F12: API
A13: 3002 | B13: ALVES | C13: Liam | D13: M | E13: 41339 | F13: COU
... A19: 3006 | B19: ANOKHIN | C19: Franck | D19: M | E19: 2012 | F19: USP
A20: 4000 | B20: ARCHAMBAUD | C20: Laura | D20: F | E20: 38929 | F20: CC2 | H20: 3166 | I20: Dos Santos | J20: Rafael | K20: H | L20: 41415 | M20: ASM TT | N20: Non Classé
A21: 4001 | B21: AREVALO | C21: Mathias | D21: M | E21: 2008 | F21: USP | H21: 3167 | I21: BAUDOU | J21: Ilyan | K21: H | L21: 41143 | M21: ASM TT | N21: Non Classé
A22: 2211 | B22: ARIS | C22: Amayas | D22: M | E22: 42103 | F22: CC2
A23: 2005 | B23: ARJOUNIN | C23: LIAM | D23: M | E23: 42258 | F23: COU
A24: 3007 | B24: ARJOUNIN | C24: NOAH | D24: M | E24: 41220 | F24: COU
A25: 4002 | B25: ARTUS | C25: Clément | D25: M | E25: 40237 | F25: USP | H25: 4140 | I25: Enzo | J25: LEMOULT | K25: H | L25: 40634 | M25: ASM TT | N25: Non Classé
A26: 4003 | B26: AUBERGER | C26: Julien | D26: M | E26: 39313 | F26: TTJ-BUC
A27: 1006 | B27: AUBERT GUENIA | C27: Lucie | D27: F | E27: 42666 | F27: TTJ-BUC
A28: 2006 | B28: AUBRY | C28: GABRIEL | D28: M | E28: 41940 | F28: CAO
A29: 1007 | B29: AUDE | C29: Jules | D29: M | E29: 42629 | F29: TTJ-BUC
A30: 2007 | B30: AUDE | C30: Paul | D30: M | E30: 41744 | F30: TTJ-BUC
A31: 3008 | B31: AUGUSTE | C31: David | D31: M | E31: 2013 | F31: USP
A32: 3009 | B32: AUXOUX | C32: Sacha | D32: M | E32: 40989 | F32: TTJ-BUC
A33: 2009 | B33: AYADI | C33: Elyes | D33: M | E33: 2015 | F33: USP
A34: 3010 | B34: AYRAULT | C34: Elio | D34: M | E34: 41607 | F34: CC2
A35: 1008 | B35: AYRAULT | C35: Mathéïs | D35: M | E35: 43182 | F35: CC2
A36: 2010 | B36: AZAMBOURG | C36: Hadrien | D36: M | E36: 41736 | F36: CC2
A37: 2011 | B37: BABAUD | C37: Sévan | D37: M | E37: 41865 | F37: COU
... A56: 1011 | B56: BELKHICHANE | C56: Ilian | D56: M | E56: 42580 | F56: TTJ-BUC
A57: 2015 | B57: BELLAHOUEL | C57: Sophia | D57: F | E57: 14/10/2014 | F57: ASV
A58: 1012 | B58: BELLIER | C58: Léo | D58: M | E58: 04/12/2017 | F58: ASV
A59: 3017 | B59: BELLIL NASCIET | C59: Nora | D59: F | E59: 41002 | F59: API
A60: 1013 | B60: BEN ABDALLAH | C60: Jude | E60: 43743 | F60: TTJ-BUC
A61: 2008 | B61: BEN GHORBAL | C61: Mohamed Awess | D61: M | E61: 41693 | F61: API
A62: 3018 | B62: BENAISSA | C62: Elias | D62: M | E62: 41607 | F62: CC2
A63: 2016 | B63: BENFDILA | C63: Amir | D63: M | E63: 41739 | F63: API
...

Sheet LISTFEMININES
A1: Dossard | B1: NOM | C1: PRENOM | D1: Sexe | E1: Naiss | F1: Club
A2: 1002 | B2: ALINE | C2: Calie | D2: F | E2: 43191 | F2: API
A3: 1006 | B3: AUBERT GUENIA | C3: Lucie | D3: F | E3: 42666 | F3: TTJ-BUC
A4: 1018 | B4: BOREL | C4: Rose | D4: F | E4: 42620 | F4: TTJ-BUC
A5: 1023 | B5: CHAVEPEYER | C5: Mako | D5: F | E5: 44097 | F5: TTJ-BUC
A6: 1024 | B6: CHAVEPEYER | C6: Niko | D6: F | E6: 42481 | F6: TTJ-BUC
A7: 1029 | B7: DELETRE | C7: Nessia | D7: F | E7: 42845 | F7: API
A8: 1032 | B8: DILLARD | C8: Charlotte | D8: F | E8: 43780 | F8: TTJ-BUC
A9: 1038 | B9: DUMAS-BELEYRIAN | C9: Margot | D9: F | E9: 43592 | F9: TTJ-BUC
A10: 1044 | B10: EL KHARRATE | C10: Sonia | D10: F | E10: 42430 | F10: API
A11: 1046 | B11: FACON | C11: Valentine | D11: F | E11: 42540 | F11: API
A12: 1054 | B12: GELBARD | C12: Cassandre | D12: F | E12: 42873 | F12: COU
A13: 1058 | B13: GLEMET | C13: Lauryn | D13: F | E13: 42384 | F13: CC2
... A33: 2004 | B33: ALAUME | C33: LOUISE | D33: F | E33: 41694 | F33: CAO
A34: 2015 | B34: BELLAHOUEL | C34: Sophia | D34: F | E34: 14/10/2014 | F34: ASV
A35: 2020 | B35: BEYER | C35: Clothilde | D35: F | E35: 42119 | F35: CC2
A36: 2025 | B36: BRAULT | C36: Auxane | D36: F | E36: 42096 | F36: API
A37: 2026 | B37: BROUILLON | C37: Shanèsia | D37: F | E37: 2014 | F37: USP
A38: 2036 | B38: CHEN | C38: Iris-Xiya | D38: F | E38: 20/03/2014 | F38: ASV
A39: 2037 | B39: CONSTANT | C39: Camille | D39: F | E39: 2014 | F39: USP
A40: 2039 | B40: CORREIA | C40: EMMY | D40: F | E40: 41816 | F40: CAO
A41: 2045 | B41: DELTHEIL | C41: Ombeline | D41: F | E41: 42185 | F41: API
A42: 2055 | B42: DUJARRIER MOY | C42: Elsa | D42: F | E42: 41807 | F42: USP
A43: 2059 | B43: FAICHE | C43: Selma | D43: F | E43: 41657 | F43: TTJ-BUC
A44: 2064 | B44: FERREIRA GALVAO | C44: Capucine | D44: F | E44: 41910 | F44: API
A45: 2091 | B45: HATRY COHEN | C45: Camille | D45: F | E45: 2014 | F45: USP
A46: 2110 | B46: LEBOURGEOIS | C46: Aliénor | D46: F | E46: 2014 | F46: USP
A47: 2125 | B47: MARQUEZ BERGE | C47: Victoria | D47: F | E47: 41697 | F47: TTJ-BUC
A48: 2132 | B48: MUKUYU-KAYA | C48: Héliana | D48: F | E48: 08/09/2015 | F48: ASV
A49: 2139 | B49: PARET | C49: Sophie | D49: F | E49: 42357 | F49: TTJ-BUC
A50: 2144 | B50: PETIT | C50: Lilou | D50: F | E50: 41772 | F50: CC2
A51: 2148 | B51: PIRES GAMBIEZ | C51: Carla | D51: F | E51: 26/02/2014 | F51: ASV
A52: 2161 | B52: RIOU BONTE | C52: Isayah | D52: F | E52: 42306 | F52: ASV
A53: 2165 | B53: ROSSI JURBERT | C53: Noelie | D53: F | E53: 42288 | F53: API
A54: 2173 | B54: SCHAEFFER | C54: Léna | D54: F | E54: 41657 | F54: TTJ-BUC
A55: 2180 | B55: SISMEIRO | C55: Célia | D55: F | E55: 41809 | F55: API
A56: 2186 | B56: TOUHIER SYLVES | C56: Alicia | D56: F | E56: 2015 | F56: USP
A57: 2195 | B57: VIGNAUD | C57: Léa | D57: F | E57: 41881 | F57: COU
A58: 3004 | B58: ANDRIEUX | C58: Laora | D58: F | E58: 41620 | F58: USP
A59: 3005 | B59: ANDRIEUX | C59: Leelouane | D59: F | E59: 40917 | F59: USP
...

Sheet TCD
A1: =Poussins!B1 -> TOURNOI DE LA VALLEE DE CHEVREUSE 2025-2026
A2: Distribution des Points
C3: Benjamins | J3: Minimes | P3: Poussins
B5: Tour | I5: Tour | Q5: Tour
A6: Club | B6: Points T1 | C6: Points T2 | D6: Points T3 | E6: Points T4 | F6: Total général | H6: Club | I6: Points T1 | J6: Points T2 | K6: Points T3 | L6: Points T4 | M6: Total général | O6: Club | P6: Points T1 | Q6: Points T2 | R6: Points T3 | S6: Points T4 | T6: Total général
A7: API | B7: 160 | H7: API | I7: 49 | O7: API | P7: 46
A8: ASM | H8: ASM | O8: ASM
A9: ASV | B9: 29 | H9: ASV | I9: 14 | O9: ASV | P9: 16
A10: VAU | B10: 22 | H10: VAU | I10: 27 | O10: VAU
A11: CAO | B11: 24 | H11: CAO | I11: 43 | O11: CAO | P11: 9
A12: CC2 | B12: 68 | H12: CC2 | I12: 72 | O12: CC2 | P12: 3
A13: COS | B13: 8 | H13: COS | I13: 1 | O13: COS | P13: 1
A14: COU | B14: 35 | H14: COU | I14: 1 | O14: COU | P14: 17
A15: TTJ-BUC | B15: 26 | H15: TTJ-BUC | I15: 31 | O15: TTJ-BUC | P15: 25
A16: USBY | B16: 73 | H16: USBY | I16: 28 | O16: USBY | P16: 5
A17: USP | B17: 77 | H17: USP | I17: 35 | O17: USP | P17: 20
A18: Total général | H18: Total général | O18: Total général
C21: Feminine | J21: Cadet/junior
B23: Tour | I23: Tour
A24: Club | B24: Points T1 | C24: Points T2 | D24: Points T3 | E24: Points T4 | F24: Total général | H24: Club | I24: Points T1 | J24: Points T2 | K24: Points T3 | L24: Points T4 | M24: Total général
A25: API | B25: 12 | H25: API | I25: 28
A26: ASM | H26: ASM | I26: 18
A27: ASV | B27: 5 | H27: ASV | I27: 4
A28: VAU | H28: VAU | I28: 22
A29: CAO | B29: 2 | H29: CAO | I29: 23
A30: CC2 | B30: 6 | H30: CC2 | I30: 41
A31: COS | B31: 3 | H31: COS
A32: COU | H32: COU
A33: TTJ-BUC | H33: TTJ-BUC | I33: 11
A34: USBY | H34: USBY | I34: 31
A35: USP | B35: 20 | H35: USP | I35: 37
A36: Total général | H36: Total général
A40: Distribution Participation
C41: Benjamins | J41: Minimes | P41: Poussins
B43: Tour | I43: Tour | Q43: Tour
A44: Club | B44: Tour 1 | C44: Tour 2 | D44: Tour 3 | E44: Tour 4 | F44: Total général | H44: Club | I44: Tour 1 | J44: Tour 2 | K44: Tour 3 | L44: Tour 4 | M44: Total général | O44: Club | P44: Tour 1 | Q44: Tour 2 | R44: Tour 3 | S44: Tour 4 | T44: Total général
A45: API | B45: 23 | H45: API | I45: 8 | O45: API | P45: 9
A46: ASM | H46: ASM | O46: ASM
A47: ASV | B47: 5 | H47: ASV | I47: 2 | O47: ASV | P47: 4
A48: VAU | B48: 4 | H48: VAU | I48: 6 | O48: VAU
...
