Workbook
Name DBenjamin: #REF!
Name DBenjamin: [1]Feuil2!$B$3
Name DCadet: #REF!
Name DCadet: [1]Feuil2!$B$5
Name DJunior: #REF!
Name DJunior: [1]Feuil2!$B$6
Name DMinime: #REF!
Name DMinime: [1]Feuil2!$B$4
Name DPoussin: #REF!
Name DPoussin: [1]Feuil2!$B$2
Name Liste_Clubs: 'Clubs-Classements'!$AC$1:$AC$13
Name VAU: 'Clubs-Classements'!$AC$1:$AC$5

Sheet Synthèse
A1: catégorie | B1: participants | C1: nb poules | D1: nb matchs poule | E1: nb matchs tableaux | F1: forfait/abandon
A2: poussins | B2: 30 | C2: 8 | D2: 42 | E2: 28
A3: benjamins | B3: 87 | C3: 22 | D3: 114 | E3: 88 | F3: 4
A4: minimes | B4: 57 | C4: 15 | D4: 69 | E4: 54
A5: cadetsjuniors | B5: 37 | C5: 10 | D5: 51 | E5: 35 | F5: 3
A6: féminines | B6: 10 | C6: 3 | D6: 9 | E6: 6 | F6: 1
B7: =SUM(B2:B6) -> 221 | C7: =SUM(C2:C6) -> 58 | D7: =SUM(D2:D6) -> 285 | E7: =SUM(E2:E6) -> 211 | F7: =SUM(F2:F6) -> 8
A9: nb total matchs | E9: =SUM(D7:E7) -> 496
A15: TVC2 | B15: prévision | C15: participants
A16: poussins | B16: 9 | C16: 16
A17: benjamins | B17: 34 | C17: 62
A18: minimes | B18: 24 | C18: 39
A19: cadetsjuniors | B19: 19 | C19: 30
A20: féminines | B20: 3 | C20: 7
C21: =SUM(C16:C20) -> 154

Sheet Poussins
B1: TOURNOI DE LA VALLEE DE CHEVREUSE 2025-2026
B3: POUSSINS (-9)
C4: pour differencier vos joueurs | H4: Tour 1 | J4: Tour 2 | L4: Tour 3 | N4: Tour 4
C5: entrer votre code club : | E5: Tout | H5: 45991 | J5: 46040 | L5: 46103 | N5: 46180
A7: Dossard | B7: NOM | C7: PRENOM | D7: Sexe | E7: Naiss | F7: Club | G7: Class. | H7: Pr. T1 | I7: Points T1 | J7: Pr. T2 | K7: Points T2 | L7: Pr. T3 | M7: Points T3 | N7: Pr. T4 | O7: Points T4 | P7: TOTAL
A8: 1042 | B8: SOLER | C8: Alexis | D8: M | E8: 43037 | F8: TTJ-BUC | G8: 500 | H8: x | I8: 11 | J8: x | K8: 7 | L8: x | P8: =SUM(I8:O8) -> 18
A9: 1057 | B9: GRANDIDIER | C9: Victor | D9: M | E9: 42825 | F9: CAO | G9: 503 | H9: x | I9: 9 | J9: x | K9: 9 | L9: x | P9: =SUM(I9:O9) -> 18
A10: 1068 | B10: ANDRIEUX | C10: Timeo | D10: M | E10: 43264 | F10: USP | G10: 508 | H10: x | I10: 8 | J10: x | K10: 6 | L10: x | P10: =SUM(I10:O10) -> 14
A11: 1086 | B11: SISMEIRO | C11: Lucas | D11: M | E11: 42820 | F11: API | G11: 501 | H11: x | I11: 8 | J11: x | K11: 5 | L11: x | P11: =SUM(I11:O11) -> 13
A12: 1089 | B12: BERBONDE | C12: Alexandre | D12: M | E12: 42968 | F12: USP | G12: 500 | H12: x | I12: 6 | J12: x | K12: 6 | L12: x | P12: =SUM(I12:O12) -> 12
A13: 1078 | B13: FRONTERA | C13: Enzo | D13: M | E13: 42927 | F13: API | G13: 501 | H13: x | I13: 7 | J13: x | K13: 5 | L13: x | P13: =SUM(I13:O13) -> 12
A14: 1069 | B14: ABBADI | C14: Neil | D14: M | E14: 42911 | F14: USP | G14: 500 | H14: x | I14: 6 | J14: x | K14: 5 | L14: x | P14: =SUM(I14:O14) -> 11
A15: 1060 | B15: RASKIN | C15: Sohan | D15: M | E15: 42802 | F15: ASV | G15: 500 | H15: x | I15: 6 | J15: x | K15: 5 | L15: x | P15: =SUM(I15:O15) -> 11
A16: 1088 | B16: THIERY | C16: Clement | D16: M | E16: 43180 | F16: API | G16: 500 | H16: x | I16: 4 | J16: x | K16: 5 | L16: x | P16: =SUM(I16:O16) -> 9
A17: 1030 | B17: FALINOWER | C17: Sael | D17: M | E17: 43154 | F17: ASV | G17: 500 | H17: x | I17: 6 | J17: x | K17: 3 | L17: x | P17: =SUM(I17:O17) -> 9
A18: 1059 | B18: TOUJANI | C18: Adel | D18: M | E18: 42816 | F18: COU | G18: 500 | H18: x | I18: 7 | J18: x | K18: 2 | P18: =SUM(I18:O18) -> 9
A19: 1087 | B19: SURMON | C19: Charlie | D19: M | E19: 43406 | F19: API | G19: 500 | H19: x | I19: 6 | J19: x | K19: 1 | L19: x | P19: =SUM(I19:O19) -> 7
A20: 1029 | B20: LEFEVRE | C20: Leen | D20: F | E20: 43181 | F20: TTJ-BUC | G20: 500 | H20: x | I20: 7 | P20: =SUM(I20:O20) -> 7
A21: 1031 | B21: PERRAUDIN | C21: Oscar | D21: M | E21: 43151 | F21: TTJ-BUC | G21: 500 | H21: x | I21: 7 | P21: =SUM(I21:O21) -> 7
A22: 1073 | B22: AUDISIO | C22: Alexandre | D22: M | E22: 43245 | F22: API | G22: 500 | H22: x | I22: 6 | L22: x | P22: =SUM(I22:O22) -> 6
A23: 1079 | B23: GARIN | C23: Valentin | D23: M | E23: 43047 | F23: API | G23: 501 | H23: x | I23: 6 | L23: x | P23: =SUM(I23:O23) -> 6
A24: 1062 | B24: DEBSKI | C24: Raphael | D24: M | E24: 42785 | F24: COU | G24: 500 | H24: x | I24: 6 | P24: =SUM(I24:O24) -> 6
A25: 1036 | B25: DRAME | C25: Moussa | D25: M | E25: 43092 | F25: USBY | G25: 500 | H25: x | I25: 3 | J25: x | K25: 1 | L25: x | P25: =SUM(I25:O25) -> 4
A26: 1018 | B26: DELAYE MOCQUARD | C26: Evangeline | D26: F | E26: 43293 | F26: ASV | G26: 500 | H26: x | I26: 3 | L26: x | P26: =SUM(I26:O26) -> 3
A27: 1039 | B27: SORTAIS | C27: Marius | D27: M | E27: 43081 | F27: COU | G27: 500 | H27: x | I27: 1 | J27: x | K27: 2 | L27: x | P27: =SUM(I27:O27) -> 3
A28: 1028 | B28: AYRAULT | C28: Matheis | D28: M | E28: 43182 | F28: CC2 | G28: 500 | H28: x | I28: 2 | P28: =SUM(I28:O28) -> 2
A29: 1074 | B29: CELMA CHAPOT | C29: Nattan | D29: M | E29: 43176 | F29: API | G29: 500 | H29: x | I29: 2 | P29: =SUM(I29:O29) -> 2
A30: 1035 | B30: BAMBA | C30: Mohamed-Adams | D30: M | E30: 43110 | F30: COU | G30: 500 | H30: x | I30: 1 | J30: x | K30: 1 | P30: =SUM(I30:O30) -> 2
A31: 1038 | B31: LAMPE | C31: Iris | D31: F | E31: 43086 | F31: USBY | G31: 500 | H31: x | I31: 2 | P31: =SUM(I31:O31) -> 2
A32: 1063 | B32: AMMAR KHODJA | C32: Yanis | D32: M | E32: 42765 | F32: COU | G32: 500 | H32: x | I32: 2 | L32: x | P32: =SUM(I32:O32) -> 2
A33: 1004 | B33: BEAUJOT | C33: Jean | D33: M | E33: 43818 | F33: CC2 | G33: 500 | H33: x | I33: 1 | P33: =SUM(I33:O33) -> 1
A34: 1019 | B34: DELAYE MOCQUARD | C34: Joscelin | D34: M | E34: 43293 | F34: ASV | G34: 500 | H34: x | I34: 1 | P34: =SUM(I34:O34) -> 1
A35: 1045 | B35: REKIK | C35: Isaac | D35: M | E35: 43031 | F35: COS | G35: 500 | H35: x | I35: 1 | P35: =SUM(I35:O35) -> 1
A36: 1083 | B36: NOUR LOUIS | C36: Lucas | D36: M | E36: 42961 | F36: API | G36: 500 | H36: x | I36: x | J36: x | K36: 1 | L36: x | P36: =SUM(I36:O36) -> 1
A37: 1072 | B37: AMOURETTE | C37: Leo | D37: M | E37: 42775 | F37: API | G37: 500 | H37: x | I37: 1 | P37: =SUM(I37:O37) -> 1
A38: 1000 | B38: BESSON DRUI | C38: Salome | D38: F | E38: 44506 | F38: CC2 | G38: 500 | P38: =SUM(I38:O38) -> 0
A39: 1001 | B39: SARLABOUT | C39: Samuel | D39: M | E39: 44497 | F39: CC2 | G39: 500 | P39: =SUM(I39:O39) -> 0
A40: 1071 | B40: ALINE | C40: Milan | D40: M | E40: 44075 | F40: API | G40: 500 | P40: =SUM(I40:O40) -> 0
A41: 1076 | B41: EHLINGER | C41: Samuel | D41: M | E41: 44000 | F41: API | G41: 500 | P41: =SUM(I41:O41) -> 0
A42: 1002 | B42: ZHAO | C42: Emy | D42: F | E42: 43983 | F42: CC2 | G42: 500 | P42: =SUM(I42:O42) -> 0
...

Sheet Minimes
B1: =Poussins!B1 -> TOURNOI DE LA VALLEE DE CHEVREUSE 2025-2026
B3: MINIMES (-13)
C4: pour differencier vos joueurs | H4: Tour 1 | J4: Tour 2 | L4: Tour 3 | N4: Tour 4
C5: entrer votre code club : | E5: Tout | H5: =Poussins!H5 -> 45991 | J5: =Poussins!J5 -> 46040 | L5: =Poussins!L5 -> 46103 | N5: =Poussins!N5 -> 46180
A7: Dossard | B7: NOM | C7: PRENOM | D7: Sexe | E7: Naiss | F7: Club | G7: Class. | H7: Pr. T1 | I7: Points T1 | J7: Pr. T2 | K7: Points T2 | L7: Pr. T3 | M7: Points T3 | N7: Pr. T4 | O7: Points T4 | P7: TOTAL
A8: 3099 | B8: ACREMANN | C8: Gabriel | D8: M | E8: 41307 | F8: USP | G8: 574 | H8: x | I8: 13 | J8: x | K8: 10 | P8: =SUM(I8:O8) -> 23
A9: 3105 | B9: DESPRIN | C9: Gaetan | D9: M | E9: 41657 | F9: API | G9: 660 | H9: x | I9: 10 | J9: x | K9: 12 | P9: =SUM(I9:O9) -> 22
A10: 3002 | B10: TAILLAN | C10: Matheis | D10: M | E10: 41986 | F10: USBY | G10: 563 | H10: x | I10: 9 | J10: x | K10: 8 | L10: x | P10: =SUM(I10:O10) -> 17
A11: 3126 | B11: VELLUET | C11: Auxence | D11: M | E11: 41975 | F11: API | G11: 636 | H11: x | I11: 9 | J11: x | K11: 8 | L11: x | P11: =SUM(I11:O11) -> 17
A12: 3125 | B12: TRICOT | C12: Adrien | D12: M | E12: 41967 | F12: API | G12: 617 | H12: x | I12: 9 | J12: x | K12: 8 | L12: x | P12: =SUM(I12:O12) -> 17
A13: 3133 | B13: RIGAUD REYMOND | C13: Valentin | D13: M | E13: 41823 | F13: TTJ-BUC | G13: 500 | H13: x | I13: 9 | J13: x | K13: 8 | P13: =SUM(I13:O13) -> 17
A14: 3027 | B14: CAUD | C14: Nael | D14: M | E14: 41773 | F14: USBY | G14: 500 | H14: x | I14: 8 | J14: x | K14: 9 | L14: x | P14: =SUM(I14:O14) -> 17
A15: 3129 | B15: BOURDEL | C15: Baptiste | D15: M | E15: 41910 | F15: CAO | G15: 532 | H15: x | I15: 8 | J15: x | K15: 7 | L15: x | P15: =SUM(I15:O15) -> 15
A16: 3089 | B16: RUBIA | C16: Eliott | D16: M | E16: 41313 | F16: VAU | G16: 500 | H16: x | I16: 8 | J16: x | K16: 7 | L16: x | P16: =SUM(I16:O16) -> 15
A17: 3094 | B17: LACROUX | C17: Gabriel | D17: M | E17: 41915 | F17: USP | G17: 500 | H17: x | I17: 8 | J17: x | K17: 6 | L17: x | P17: =SUM(I17:O17) -> 14
A18: 3095 | B18: CHEN | C18: Alexandre | D18: M | E18: 41823 | F18: USP | G18: 500 | H18: x | I18: 7 | J18: x | K18: 7 | L18: x | P18: =SUM(I18:O18) -> 14
A19: 3056 | B19: MAKSIMOVIKJ | C19: Noah | D19: M | E19: 41471 | F19: CC2 | G19: 500 | H19: x | I19: 7 | J19: x | K19: 7 | L19: x | P19: =SUM(I19:O19) -> 14
A20: 3037 | B20: CHEN | C20: Iris-Xiya | D20: F | E20: 41718 | F20: ASV | G20: 500 | H20: x | I20: 7 | J20: x | K20: 6 | L20: x | P20: =SUM(I20:O20) -> 13
A21: 3107 | B21: FLAMENT | C21: Emilien | D21: M | E21: 41700 | F21: API | G21: 525 | H21: x | I21: 7 | J21: x | K21: 6 | L21: x | P21: =SUM(I21:O21) -> 13
A22: 3060 | B22: QU | C22: Theo | D22: M | E22: 41435 | F22: CAO | G22: 500 | H22: x | I22: 7 | J22: x | K22: 6 | P22: =SUM(I22:O22) -> 13
A23: 3121 | B23: PERONNE | C23: Aymeric | D23: M | E23: 41745 | F23: API | G23: 715 | H23: x | I23: 11 | P23: =SUM(I23:O23) -> 11
A24: 3080 | B24: ADOUE | C24: Theo | D24: M | E24: 41973 | F24: VAU | G24: 500 | H24: x | I24: 7 | J24: x | K24: 3 | L24: x | P24: =SUM(I24:O24) -> 10
A25: 3028 | B25: SEGUIN | C25: Evariste | D25: M | E25: 41773 | F25: CC2 | G25: 619 | H25: x | I25: 10 | L25: x | P25: =SUM(I25:O25) -> 10
A26: 3043 | B26: CHAPPUIS | C26: Alexandre | D26: M | E26: 41676 | F26: CC2 | G26: 500 | H26: x | I26: 4 | J26: x | K26: 6 | P26: =SUM(I26:O26) -> 10
A27: 3123 | B27: SEGRESTAN | C27: Tiago | D27: M | E27: 41509 | F27: API | G27: 500 | J27: x | K27: 9 | L27: x | P27: =SUM(I27:O27) -> 9
A28: 3010 | B28: CARPENTIER | C28: Louis | D28: M | E28: 41935 | F28: CC2 | G28: 500 | H28: x | I28: 8 | P28: =SUM(I28:O28) -> 8
A29: 3139 | B29: HAUTREUX | C29: Baptiste | D29: M | E29: 41862 | F29: USBY | G29: 500 | H29: x | I29: 2 | J29: x | K29: 6 | L29: x | P29: =SUM(I29:O29) -> 8
A30: 3022 | B30: BOECKMAN | C30: Julian | D30: M | E30: 41834 | F30: CAO | G30: 500 | H30: x | I30: 7 | J30: x | K30: 1 | P30: =SUM(I30:O30) -> 8
A31: 3050 | B31: AYRAULT | C31: Elio | D31: M | E31: 41607 | F31: CC2 | G31: 500 | H31: x | I31: 8 | P31: =SUM(I31:O31) -> 8
A32: 3068 | B32: HEZARD | C32: Robin | D32: M | E32: 41376 | F32: CAO | G32: 500 | H32: x | I32: 8 | P32: =SUM(I32:O32) -> 8
A33: 3071 | B33: DARNIEAUD | C33: Florent | D33: M | E33: 41349 | F33: CC2 | G33: 500 | H33: x | I33: 8 | P33: =SUM(I33:O33) -> 8
A34: 3005 | B34: LALEU | C34: Vadim | D34: M | E34: 41979 | F34: CC2 | G34: 500 | H34: x | I34: 7 | P34: =SUM(I34:O34) -> 7
A35: 3138 | B35: COSTA | C35: Axel | D35: M | E35: 41862 | F35: ASV | G35: 500 | H35: x | I35: 7 | L35: x | P35: =SUM(I35:O35) -> 7
A36: 3137 | B36: LAVERRE | C36: Arthur | D36: M | E36: 41862 | F36: CAO | G36: 500 | H36: x | I36: 7 | P36: =SUM(I36:O36) -> 7
A37: 3020 | B37: ZIMMERMANN | C37: Gabriel | D37: M | E37: 41862 | F37: CC2 | G37: 500 | H37: x | I37: 7 | P37: =SUM(I37:O37) -> 7
A38: 3114 | B38: LEBERT | C38: Elliot | D38: M | E38: 41730 | F38: API | G38: 576 | J38: x | K38: 7 | L38: x | P38: =SUM(I38:O38) -> 7
A39: 3097 | B39: ROUX | C39: Teïas | D39: M | E39: 41639 | F39: USP | G39: 500 | H39: x | I39: 7 | P39: =SUM(I39:O39) -> 7
A40: 3096 | B40: ANDRIEUX | C40: Laora | D40: F | E40: 41620 | F40: USP | G40: 575 | J40: x | K40: 7 | L40: x | P40: =SUM(I40:O40) -> 7
A41: 3055 | B41: BIRYUKOV | C41: Aleksandr | D41: M | E41: 41482 | F41: CC2 | G41: 500 | H41: x | I41: 7 | P41: =SUM(I41:O41) -> 7
A42: 3134 | B42: LERUSTE | C42: Corentin | D42: M | E42: 41455 | F42: TTJ-BUC | G42: 500 | H42: x | I42: 7 | P42: =SUM(I42:O42) -> 7
...

Sheet Benjamins
B1: TOURNOI DE LA VALLEE DE CHEVREUSE 2022-2023
B3: BENJAMINS (-11)
C4: pour differencier vos joueurs | H4: Tour 1 | J4: Tour 2 | L4: Tour 3 | N4: Tour 4
C5: entrer votre code club : | E5: Tout | H5: =Poussins!H5 -> 45991 | J5: =Poussins!J5 -> 46040 | L5: =Poussins!L5 -> 46103 | N5: =Poussins!N5 -> 46180
A7: Dossard | B7: NOM | C7: PRENOM | D7: Sexe | E7: Naiss | F7: Club | G7: Class. | H7: Pr. T1 | I7: Points T1 | J7: Pr. T2 | K7: Points T2 | L7: Pr. T3 | M7: Points T3 | N7: Pr. T4 | O7: Points T4 | P7: TOTAL
A8: 2166 | B8: LEBERT | C8: Raphael | D8: M | E8: 42526 | F8: API | G8: 548 | H8: x | I8: 15 | J8: x | K8: 12 | P8: =SUM(I8:O8) -> 27
A9: 2112 | B9: DESRETTES | C9: Gabin | D9: M | E9: 42010 | F9: CC2 | G9: 500 | H9: x | I9: 12 | J9: x | K9: 11 | P9: =SUM(I9:O9) -> 23
A10: 2139 | B10: CHAPPERT | C10: William | D10: M | E10: 42239 | F10: USP | G10: 500 | H10: x | I10: 12 | J10: x | K10: 10 | P10: =SUM(I10:O10) -> 22
A11: 2134 | B11: TESSERA | C11: Adrien | D11: M | E11: 42095 | F11: USP | G11: 500 | H11: x | I11: 11 | J11: x | K11: 11 | P11: =SUM(I11:O11) -> 22
A12: 2168 | B12: MAILLAUD | C12: Merlin | D12: M | E12: 42449 | F12: API | G12: 500 | H12: x | I12: 11 | J12: x | K12: 10 | P12: =SUM(I12:O12) -> 21
A13: 2165 | B13: LEBERT | C13: Arthur | D13: M | E13: 42526 | F13: API | G13: 501 | H13: x | I13: 11 | J13: x | K13: 9 | P13: =SUM(I13:O13) -> 20
A14: 2039 | B14: GOZZI | C14: Matteo | D14: M | E14: 42456 | F14: COU | G14: 500 | H14: x | I14: 10 | J14: x | K14: 10 | P14: =SUM(I14:O14) -> 20
A15: 2147 | B15: CARDON | C15: Antoine | D15: M | E15: 42014 | F15: API | G15: 500 | H15: x | I15: 10 | J15: x | K15: 10 | P15: =SUM(I15:O15) -> 20
A16: 2040 | B16: HEURLEY | C16: Matei | D16: M | E16: 42454 | F16: CC2 | G16: 500 | H16: x | I16: 10 | J16: x | K16: 9 | P16: =SUM(I16:O16) -> 19
A17: 2180 | B17: COUSSEMENT | C17: Raphael | D17: M | E17: 42390 | F17: USP | G17: 500 | H17: x | I17: 10 | J17: x | K17: 9 | P17: =SUM(I17:O17) -> 19
A18: 2104 | B18: VEDRENNE | C18: Thiago | D18: M | E18: 42065 | F18: CC2 | G18: 500 | H18: x | I18: 10 | J18: x | K18: 9 | P18: =SUM(I18:O18) -> 19
A19: 2094 | B19: ROUGEMAIILE | C19: Ethan | D19: M | E19: 42118 | F19: CAO | G19: 500 | H19: x | I19: 9 | J19: x | K19: 9 | P19: =SUM(I19:O19) -> 18
A20: 2120 | B20: GAILLARD | C20: Owen | D20: M | E20: 42361 | F20: VAU | G20: 500 | H20: x | I20: 9 | J20: x | K20: 8 | P20: =SUM(I20:O20) -> 17
A21: 2132 | B21: BAJARD | C21: Timeo | D21: M | E21: 42334 | F21: USP | G21: 500 | H21: x | I21: 9 | J21: x | K21: 8 | P21: =SUM(I21:O21) -> 17
A22: 2083 | B22: RASKIN | C22: Rayan | D22: M | E22: 42205 | F22: ASV | G22: 500 | H22: x | I22: 10 | J22: x | K22: 7 | P22: =SUM(I22:O22) -> 17
A23: 2163 | B23: LACROIX MARTIN | C23: Adam | D23: M | E23: 42088 | F23: API | G23: 500 | H23: x | I23: 9 | J23: x | K23: 8 | P23: =SUM(I23:O23) -> 17
A24: 2148 | B24: CORTES | C24: Rafael | D24: M | E24: 42637 | F24: API | G24: 500 | H24: x | I24: 8 | J24: x | K24: 8 | P24: =SUM(I24:O24) -> 16
A25: 2043 | B25: BADUEL | C25: Edgar | D25: M | E25: 42411 | F25: CC2 | G25: 500 | H25: x | I25: 8 | J25: x | K25: 8 | P25: =SUM(I25:O25) -> 16
A26: 2181 | B26: GARNIER | C26: Eden | D26: M | E26: 42411 | F26: USBY | G26: 500 | H26: x | I26: 9 | J26: x | K26: 7 | P26: =SUM(I26:O26) -> 16
A27: 2082 | B27: GONZALEZ | C27: Esteban | D27: M | E27: 42208 | F27: TTJ-BUC | G27: 500 | H27: x | I27: 9 | J27: x | K27: 7 | P27: =SUM(I27:O27) -> 16
A28: 2162 | B28: JACOBERGER | C28: Ethan | D28: M | E28: 42066 | F28: API | G28: 500 | H28: x | I28: 9 | J28: x | K28: 7 | P28: =SUM(I28:O28) -> 16
A29: 2160 | B29: FRANCOIS | C29: Arthur | D29: M | E29: 42055 | F29: API | G29: 500 | H29: x | I29: 9 | J29: x | K29: 7 | P29: =SUM(I29:O29) -> 16
A30: 2161 | B30: GENDRON CARALP | C30: Leo | D30: M | E30: 42574 | F30: API | G30: 500 | H30: x | I30: 8 | J30: x | K30: 7 | P30: =SUM(I30:O30) -> 15
A31: 2022 | B31: DURAND | C31: Mathis | D31: M | E31: 42570 | F31: CC2 | G31: 500 | J31: x | K31: 14 | P31: =SUM(I31:O31) -> 14
A32: 2028 | B32: NGUYEN | C32: Nolan | D32: M | E32: 42538 | F32: CAO | G32: 511 | H32: x | I32: 4 | J32: x | K32: 9 | P32: =SUM(I32:O32) -> 13
A33: 2142 | B33: AUDISIO | C33: Julian | D33: M | E33: 42508 | F33: API | G33: 500 | H33: x | I33: 9 | J33: x | K33: 4 | P33: =SUM(I33:O33) -> 13
A34: 2183 | B34: BASSIR | C34: Ryan | D34: M | E34: 42469 | F34: USP | G34: 500 | H34: x | I34: 9 | J34: x | K34: 4 | P34: =SUM(I34:O34) -> 13
A35: 2051 | B35: SEMO | C35: Valentin | D35: M | E35: 42382 | F35: CC2 | G35: 539 | H35: x | I35: 13 | P35: =SUM(I35:O35) -> 13
A36: 2052 | B36: BICHON-KOUACHI | C36: Joseph | D36: M | E36: 42377 | F36: TTJ-BUC | G36: 500 | H36: x | I36: 5 | J36: x | K36: 8 | P36: =SUM(I36:O36) -> 13
A37: 2103 | B37: MICHEL | C37: Kendrick | D37: M | E37: 42065 | F37: COU | G37: 500 | H37: x | I37: 4 | J37: x | K37: 9 | P37: =SUM(I37:O37) -> 13
A38: 2019 | B38: DRAME | C38: Ibrahim | D38: M | E38: 42633 | F38: USBY | G38: 500 | H38: x | I38: 9 | J38: x | K38: 3 | P38: =SUM(I38:O38) -> 12
A39: 2036 | B39: BASSET | C39: Theo | D39: M | E39: 42469 | F39: CAO | G39: 500 | H39: x | I39: 4 | J39: x | K39: 8 | P39: =SUM(I39:O39) -> 12
A40: 2062 | B40: RIOU BONTE | C40: Isayah | D40: M | E40: 42306 | F40: ASV | G40: 500 | H40: x | I40: 11 | P40: =SUM(I40:O40) -> 11
A41: 2152 | B41: DELTHEIL | C41: Gauvin | D41: M | E41: 42178 | F41: API | G41: 500 | H41: x | I41: 4 | J41: x | K41: 7 | P41: =SUM(I41:O41) -> 11
A42: 2155 | B42: DOUBLET DECABRAS | C42: Pierre | D42: M | E42: 42669 | F42: API | G42: 500 | H42: x | I42: 8 | J42: x | K42: 2 | P42: =SUM(I42:O42) -> 10
...

Sheet Cadets-Juniors
B1: =Poussins!B1 -> TOURNOI DE LA VALLEE DE CHEVREUSE 2025-2026
B3: CADETS-JUNIORS (-15 et -18)
C4: pour differencier vos joueurs | H4: Tour 1 | J4: Tour 2 | L4: Tour 3 | N4: Tour 4
C5: entrer votre code club : | E5: Tout | H5: =Poussins!H5 -> 45991 | J5: =Poussins!J5 -> 46040 | L5: =Poussins!L5 -> 46103 | N5: =Poussins!N5 -> 46180
A7: Dossard | B7: NOM | C7: PRENOM | D7: Sexe | E7: Naiss | F7: Club | G7: Class. | H7: Pr. T1 | I7: Points T1 | J7: Pr. T2 | K7: Points T2 | L7: Pr. T3 | M7: Points T3 | N7: Pr. T4 | O7: Points T4 | P7: TOTAL
A8: 4001 | B8: ALCIDE | C8: Ethan | D8: M | E8: 41032 | F8: USP | G8: 500 | H8: x | I8: 1 | P8: =SUM(I8:O8) -> 1
A9: 4002 | B9: ANDRIEUX | C9: Leelouane | D9: F | E9: 40917 | F9: USP | G9: 500 | H9: x | I9: 8 | J9: X | K9: 8 | L9: x | P9: =SUM(I9:O9) -> 16
A10: 4003 | B10: BALIGAND | C10: Corentin | D10: M | E10: 40861 | F10: CAO | G10: 647 | H10: x | I10: 8 | J10: x | K10: 6 | P10: =SUM(I10:O10) -> 14
A11: 4004 | B11: BAUDOU | C11: Ilyan | D11: M | E11: 40909 | F11: ASM | G11: 500 | H11: x | I11: 2 | J11: x | K11: 4 | L11: x | P11: =SUM(I11:O11) -> 6
A12: 4005 | B12: BEAUVINEAU | C12: Ethan | D12: M | E12: 41002 | F12: USBY | G12: 500 | H12: x | I12: 2 | L12: x | P12: =SUM(I12:O12) -> 2
A13: 4006 | B13: BELLIL NASCIET | C13: Nora | D13: F | E13: 41002 | F13: API | G13: 500 | P13: =SUM(I13:O13) -> 0
A14: 4007 | B14: BERENBACH | C14: Fabian | D14: M | E14: 41267 | F14: VAU | G14: 500 | H14: x | I14: 2 | J14: x | K14: 1 | L14: x | P14: =SUM(I14:O14) -> 3
A15: 4008 | B15: BEREZIAT | C15: Zachary | D15: M | E15: 41009 | F15: USBY | G15: 517 | P15: =SUM(I15:O15) -> 0
A16: 4009 | B16: BHATTI | C16: Moussa | D16: M | E16: 41118 | F16: USP | G16: 500 | P16: =SUM(I16:O16) -> 0
A17: 4010 | B17: BIELANDE | C17: Emmy | D17: F | E17: 41272 | F17: CC2 | G17: 500 | J17: x | K17: 6 | L17: x | P17: =SUM(I17:O17) -> 6
A18: 4011 | B18: BITAN | C18: Laura | D18: F | E18: 40602 | F18: COS | G18: 500 | P18: =SUM(I18:O18) -> 0
A19: 4012 | B19: BOLLIG | C19: Lucas | D19: M | E19: 41205 | F19: COU | G19: 500 | P19: =SUM(I19:O19) -> 0
A20: 4013 | B20: BONNISSEAU | C20: Tanguy | D20: M | E20: 40495 | F20: TTJ-BUC | G20: 500 | P20: =SUM(I20:O20) -> 0
A21: 4014 | B21: BOSC-VIRTON | C21: Milan | D21: M | E21: 41088 | F21: VAU | G21: 500 | J21: x | K21: 2 | P21: =SUM(I21:O21) -> 2
A22: 4015 | B22: CAILLERIE | C22: Marie | D22: F | E22: 40711 | F22: CAO | G22: 500 | P22: =SUM(I22:O22) -> 0
A23: 4016 | B23: CANARD | C23: Laura | D23: F | E23: 40897 | F23: CAO | G23: 500 | P23: =SUM(I23:O23) -> 0
A24: 4017 | B24: CAUSSE | C24: Axel | D24: M | E24: 41263 | F24: API | G24: 500 | H24: x | I24: 7 | P24: =SUM(I24:O24) -> 7
A25: 4018 | B25: CORDE | C25: Jules | D25: M | E25: 40870 | F25: API | G25: 1134 | P25: =SUM(I25:O25) -> 0
A26: 4019 | B26: CORTES | C26: Nathan | D26: M | E26: 40269 | F26: API | G26: 500 | P26: =SUM(I26:O26) -> 0
A27: 4020 | B27: DALLERAC | C27: Caelan | D27: M | E27: 40865 | F27: USBY | G27: 538 | H27: x | I27: 9 | J27: x | K27: 9 | L27: x | P27: =SUM(I27:O27) -> 18
A28: 4021 | B28: DE BAENE | C28: Maxence | D28: M | E28: 40465 | F28: VAU | G28: 500 | P28: =SUM(I28:O28) -> 0
A29: 4022 | B29: DEMOISSON NARIYAMA | C29: Sasha | D29: M | E29: 41230 | F29: TTJ-BUC | G29: 500 | H29: x | I29: 9 | P29: =SUM(I29:O29) -> 9 | Z29: USBY
A30: 4023 | B30: DESPRIN | C30: Lya | D30: F | E30: 40922 | F30: API | G30: 500 | P30: =SUM(I30:O30) -> 0
A31: 4024 | B31: D'HUART | C31: Gaetan | D31: M | E31: 40713 | F31: COU | G31: 500 | P31: =SUM(I31:O31) -> 0
A32: 4025 | B32: DRAY | C32: Luca | D32: M | E32: 40870 | F32: CC2 | G32: 500 | H32: x | I32: 2 | P32: =SUM(I32:O32) -> 2 | Z32: ORS
A33: 4026 | B33: FRANCOIS | C33: Nathanael | D33: M | E33: 40701 | F33: TTJ-BUC | G33: 500 | H33: x | I33: 2 | P33: =SUM(I33:O33) -> 2
A34: 4027 | B34: FUHRMANN | C34: Eva | D34: F | E34: 40738 | F34: USP | G34: 500 | H34: x | I34: 7 | J34: x | K34: 6 | L34: x | P34: =SUM(I34:O34) -> 13
A35: 4028 | B35: FUZIER | C35: Pierre | D35: M | E35: 41104 | F35: USBY | G35: 500 | H35: x | I35: 2 | P35: =SUM(I35:O35) -> 2
A36: 4029 | B36: GAJECKI | C36: Justin | D36: M | E36: 41104 | F36: API | G36: 940 | P36: =SUM(I36:O36) -> 0
A37: 4030 | B37: GALAND | C37: Adel | D37: M | E37: 41051 | F37: VAU | G37: 575 | H37: x | I37: 9 | J37: x | K37: 6 | P37: =SUM(I37:O37) -> 15
A38: 4031 | B38: GALTIER | C38: Ethan | D38: M | E38: 41123 | F38: API | G38: 500 | P38: =SUM(I38:O38) -> 0
A39: 4032 | B39: GAUTHIER | C39: Mathis | D39: M | E39: 41089 | F39: VAU | G39: 500 | H39: x | I39: 8 | L39: x | P39: =SUM(I39:O39) -> 8
A40: 4033 | B40: GEISEN | C40: Jeremie | D40: M | E40: 40958 | F40: CAO | G40: 500 | P40: =SUM(I40:O40) -> 0
A41: 4034 | B41: GENIAUT | C41: Remi | D41: M | E41: 40165 | F41: API | G41: 500 | P41: =SUM(I41:O41) -> 0
A42: 4035 | B42: GIRAUD | C42: Jules | D42: M | E42: 40694 | F42: API | G42: 500 | P42: =SUM(I42:O42) -> 0
...

Sheet Feminines
B1: =Poussins!B1 -> TOURNOI DE LA VALLEE DE CHEVREUSE 2025-2026
B3: FEMININES (toutes catégories)
C4: pour differencier vos joueurs | H4: Tour 1 | J4: Tour 2 | L4: Tour 3 | N4: Tour 4
C5: entrer votre code club : | E5: Tout | H5: =Poussins!H5 -> 45991 | J5: =Poussins!J5 -> 46040 | L5: =Poussins!L5 -> 46103 | N5: =Poussins!N5 -> 46180
A7: Dossard | B7: NOM | C7: PRENOM | D7: Sexe | E7: Naiss | F7: Club | G7: Class. | H7: Pr. T1 | I7: Points T1 | J7: Pr. T2 | K7: Points T2 | L7: Pr. T3 | M7: Points T3 | N7: Pr. T4 | O7: Points T4 | P7: TOTAL
A8: 4002 | B8: ANDRIEUX | C8: Leelouane | D8: F | E8: 40917 | F8: USP | G8: 500 | H8: x | I8: 9 | J8: x | K8: 9 | L8: x | P8: =SUM(I8:O8) -> 18
A9: 3119 | B9: MARQUES | C9: Fanny | D9: F | E9: 41529 | F9: API | G9: 500 | H9: x | I9: 7 | J9: x | K9: 6 | L9: x | P9: =SUM(I9:O9) -> 13
A10: 4010 | B10: BIELANDE | C10: Emmy | D10: F | E10: 41272 | F10: CC2 | G10: 500 | H10: x | I10: 6 | J10: x | K10: 5 | L10: x | P10: =SUM(I10:O10) -> 11
A11: 3037 | B11: CHEN | C11: Iris-Xiya | D11: F | E11: 41718 | F11: ASV | G11: 500 | H11: x | I11: 5 | J11: x | K11: 3 | L11: x | P11: =SUM(I11:O11) -> 8
A12: 3096 | B12: ANDRIEUX | C12: Laora | D12: F | E12: 41620 | F12: USP | G12: 575 | J12: x | K12: 7 | L12: x | P12: =SUM(I12:O12) -> 7
A13: 4027 | B13: FUHRMANN | C13: Eva | D13: F | E13: 40738 | F13: USP | G13: 500 | H13: x | I13: 5 | J13: x | K13: 2 | L13: x | P13: =SUM(I13:O13) -> 7
A14: 4079 | B14: POULAIN EMOND | C14: Loa | D14: F | E14: 39279 | F14: USP | G14: 500 | H14: x | I14: 6 | L14: x | P14: =SUM(I14:O14) -> 6
A15: 2174 | B15: ROSSI JURBERT | C15: Noelie | D15: F | E15: 42288 | F15: API | G15: 500 | H15: x | I15: 5 | P15: =SUM(I15:O15) -> 5
A16: 3124 | B16: SISMEIRO | C16: Celia | D16: F | E16: 41809 | F16: API | G16: 500 | J16: x | K16: 5 | L16: x | P16: =SUM(I16:O16) -> 5
A17: 4011 | B17: BITAN | C17: Laura | D17: F | E17: 40602 | F17: COS | G17: 500 | H17: x | I17: 3 | P17: =SUM(I17:O17) -> 3
A18: 3041 | B18: ALAUME | C18: Louise | D18: F | E18: 41694 | F18: CAO | G18: 500 | H18: x | I18: 2 | P18: =SUM(I18:O18) -> 2
A19: 1000 | B19: BESSON DRUI | C19: Salome | D19: F | E19: 44506 | F19: CC2 | G19: 500 | P19: =SUM(I19:O19) -> 0
A20: 1002 | B20: ZHAO | C20: Emy | D20: F | E20: 43983 | F20: CC2 | G20: 500 | P20: =SUM(I20:O20) -> 0
A21: 1003 | B21: LALEU | C21: Alicia | D21: F | E21: 43962 | F21: CC2 | G21: 500 | P21: =SUM(I21:O21) -> 0
A22: 1005 | B22: PARET | C22: Sophie | D22: F | E22: 43818 | F22: TTJ-BUC | G22: 500 | P22: =SUM(I22:O22) -> 0
A23: 1006 | B23: GROSJEAN | C23: Jade | D23: F | E23: 43694 | F23: CC2 | G23: 500 | P23: =SUM(I23:O23) -> 0
A24: 1008 | B24: RETHO | C24: Lucie | D24: F | E24: 43645 | F24: CC2 | G24: 500 | P24: =SUM(I24:O24) -> 0
A25: 1014 | B25: PAEZ | C25: Elena | D25: F | E25: 43409 | F25: COU | G25: 500 | P25: =SUM(I25:O25) -> 0
A26: 1067 | B26: RIEL LEGROS | C26: Letty | D26: F | E26: 43332 | F26: VAU | G26: 500 | P26: =SUM(I26:O26) -> 0
A27: 1018 | B27: DELAYE MOCQUARD | C27: Evangeline | D27: F | E27: 43293 | F27: ASV | G27: 500 | L27: x | P27: =SUM(I27:O27) -> 0
A28: 1025 | B28: ZHAO | C28: Mia | D28: F | E28: 43226 | F28: CC2 | G28: 500 | P28: =SUM(I28:O28) -> 0
A29: 1070 | B29: ALINE | C29: Calie | D29: F | E29: 43191 | F29: API | G29: 500 | P29: =SUM(I29:O29) -> 0
A30: 1029 | B30: LEFEVRE | C30: Leen | D30: F | E30: 43181 | F30: TTJ-BUC | G30: 500 | P30: =SUM(I30:O30) -> 0
A31: 1032 | B31: JOURDAN | C31: Amandine | D31: F | E31: 43121 | F31: TTJ-BUC | G31: 500 | P31: =SUM(I31:O31) -> 0
A32: 1033 | B32: WAQAQ | C32: Ayesha | D32: F | E32: 43120 | F32: COU | G32: 500 | P32: =SUM(I32:O32) -> 0
A33: 1038 | B33: LAMPE | C33: Iris | D33: F | E33: 43086 | F33: USBY | G33: 500 | P33: =SUM(I33:O33) -> 0
A34: 1081 | B34: LEBAS | C34: Lucie | D34: F | E34: 43081 | F34: API | G34: 500 | P34: =SUM(I34:O34) -> 0
A35: 1052 | B35: RIGAUD | C35: Eva | D35: F | E35: 42878 | F35: TTJ-BUC | G35: 500 | P35: =SUM(I35:O35) -> 0
A36: 1075 | B36: DELETRE | C36: Nessia | D36: F | E36: 42845 | F36: API | G36: 500 | P36: =SUM(I36:O36) -> 0
A37: 1058 | B37: LANDRAGIN | C37: Amelie | D37: F | E37: 42820 | F37: CAO | G37: 500 | P37: =SUM(I37:O37) -> 0
A38: 2000 | B38: PERES | C38: Chloe | D38: F | E38: 42731 | F38: TTJ-BUC | G38: 500 | P38: =SUM(I38:O38) -> 0
A39: 2171 | B39: N'SONGAN | C39: Lya | D39: F | E39: 42697 | F39: API | G39: 500 | P39: =SUM(I39:O39) -> 0
A40: 2012 | B40: AUBERT | C40: Lucie | D40: F | E40: 42666 | F40: TTJ-BUC | G40: 500 | P40: =SUM(I40:O40) -> 0
A41: 2024 | B41: DUMAS | C41: Camille | D41: F | E41: 42568 | F41: TTJ-BUC | G41: 500 | P41: =SUM(I41:O41) -> 0
A42: 2042 | B42: CADERE ROEHRIG | C42: Emma | D42: F | E42: 42416 | F42: TTJ-BUC | G42: 500 | P42: =SUM(I42:O42) -> 0
...

Sheet Tableaux Croisés
A1: =Poussins!B1 -> TOURNOI DE LA VALLEE DE CHEVREUSE 2025-2026
A2: Distribution des Points
C3: Benjamins | J3: Minimes | P3: Poussins
B5: Tour | I5: Tour | O5: Poussins
A6: Club | B6: Points T1 | C6: Points T2 | D6: Points T3 | E6: Points T4 | F6: Total général | H6: Club | I6: Points T1 | J6: Points T2 | K6: Points T3 | L6: Points T4 | M6: Total général | O6: Club | P6: Points T1 | Q6: Points T2 | R6: Points T3 | S6: Points T4 | T6: Total général
A7: API | B7: 160 | C7: 113 | F7: 273 | H7: API | I7: 49 | J7: 57 | M7: 106 | O7: API | P7: 40 | Q7: 17 | T7: 57
A8: ASM | H8: ASM | J8: 2 | M8: 2 | O8: ASM
A9: ASV | B9: 29 | C9: 7 | F9: 36 | H9: ASV | I9: 14 | J9: 6 | M9: 20 | O9: ASV | P9: 16 | Q9: 8 | T9: 24
A10: CAO | B10: 24 | C10: 35 | F10: 59 | H10: CAO | I10: 43 | J10: 15 | M10: 58 | O10: CAO | P10: 9 | Q10: 9 | T10: 18
A11: CC2 | B11: 68 | C11: 70 | F11: 138 | H11: CC2 | I11: 72 | J11: 34 | M11: 106 | O11: CC2 | P11: 3 | T11: 3
A12: COS | B12: 8 | F12: 8 | H12: COS | I12: 1 | M12: 1 | O12: COS | P12: 1 | T12: 1
A13: COU | B13: 35 | C13: 37 | F13: 72 | H13: COU | I13: 1 | J13: 1 | M13: 2 | O13: COU | P13: 17 | Q13: 5 | T13: 22
A14: TTJ-BUC | B14: 26 | C14: 17 | F14: 43 | H14: TTJ-BUC | I14: 31 | J14: 13 | M14: 44 | O14: TTJ-BUC | P14: 25 | Q14: 7 | T14: 32
A15: USBY | B15: 73 | C15: 22 | F15: 95 | H15: USBY | I15: 28 | J15: 26 | M15: 54 | O15: USBY | P15: 5 | Q15: 1 | T15: 6
A16: USP | B16: 77 | C16: 54 | F16: 131 | H16: USP | I16: 35 | J16: 43 | M16: 78 | O16: USP | P16: 20 | Q16: 17 | T16: 37
A17: VAU | B17: 22 | C17: 11 | F17: 33 | H17: VAU | I17: 27 | J17: 10 | M17: 37 | O17: VAU
A18: Total général | B18: 522 | C18: 366 | F18: 888 | H18: Total général | I18: 301 | J18: 207 | M18: 508 | O18: Total général | P18: 136 | Q18: 64 | T18: 200
C21: Feminine | J21: Cadet/junior
B23: Tour | I23: Tour
A24: Club | B24: Points T1 | C24: Points T2 | D24: Points T3 | E24: Points T4 | F24: Total général | H24: Club | I24: Points T1 | J24: Points T2 | K24: Points T3 | L24: Points T4 | M24: Total général
A25: API | B25: 12 | C25: 11 | F25: 23 | H25: API | I25: 28 | J25: 6 | M25: 34
A26: ASM | H26: ASM | I26: 18 | J26: 12 | M26: 30
A27: ASV | B27: 5 | C27: 3 | F27: 8 | H27: ASV | I27: 4 | M27: 4
A28: CAO | B28: 2 | F28: 2 | H28: CAO | I28: 23 | J28: 21 | M28: 44
A29: CC2 | B29: 6 | C29: 5 | F29: 11 | H29: CC2 | I29: 41 | J29: 48 | M29: 89
A30: COS | B30: 3 | F30: 3 | H30: COS
A31: COU | H31: COU | J31: 6 | M31: 6
A32: TTJ-BUC | H32: TTJ-BUC | I32: 11 | M32: 11
A33: USBY | H33: USBY | I33: 31 | J33: 19 | M33: 50
A34: USP | B34: 20 | C34: 18 | F34: 38 | H34: USP | I34: 37 | J34: 35 | M34: 72
A35: VAU | H35: VAU | I35: 22 | J35: 18 | M35: 40
A36: Total général | B36: 48 | C36: 37 | F36: 85 | H36: Total général | I36: 215 | J36: 165 | M36: 380
A40: Distribution Participation
C41: Benjamins | J41: Minimes | P41: Poussins
B43: Tour | I43: Tour | O43: Nombre de Valeur | P43: Tour
A44: Club | B44: Tour 1 | C44: Tour 2 | D44: Tour 3 | E44: Tour 4 | F44: Total général | H44: Club | I44: Tour 1 | J44: Tour 2 | K44: Tour 3 | L44: Tour 4 | M44: Total général | O44: Club | P44: Pr. T1 | Q44: Pr. T2 | R44: Pr. T3 | S44: Pr. T4 | T44: Total général
A45: API | B45: 23 | C45: 18 | F45: 41 | H45: API | I45: 8 | J45: 7 | M45: 15 | O45: API | P45: 9 | Q45: 5 | T45: 14
A46: ASM | H46: ASM | J46: 1 | M46: 1 | O46: ASM
A47: ASV | B47: 5 | C47: 1 | F47: 6 | H47: ASV | I47: 2 | J47: 1 | M47: 3 | O47: ASV | P47: 4 | Q47: 2 | T47: 6
A48: CAO | B48: 5 | C48: 5 | F48: 10 | H48: CAO | I48: 8 | J48: 4 | M48: 12 | O48: CAO | P48: 1 | Q48: 1 | T48: 2
...

Sheet Clubs-Classements
B1: =Poussins!B1 -> TOURNOI DE LA VALLEE DE CHEVREUSE 2025-2026
AC2: Tout
B3: TOTAL-CLUBS | AC3: API
AC4: ASM
C5: 1er Tour | I5: 2nd Tour | O5: 3ème Tour | U5: 4ème Tour | AC5: ASV
C6: =Benjamins!H5 -> 45991 | I6: 46040 | O6: =Benjamins!L5 -> 46103 | U6: =Benjamins!N5 -> 46180 | AC6: CAO
C7: POUS. | D7: BENJ. | E7: MINI. | F7: CAD.- JUNIO. | G7: FEM. | H7: TOTAL | I7: POUS. | J7: BENJ. | K7: MINI. | L7: CAD.- JUNIO. | M7: FEM. | N7: TOTAL | O7: POUS. | P7: BENJ. | Q7: MINI. | R7: CAD.- JUNIO. | S7: FEM. | T7: TOTAL | U7: POUS. | V7: BENJ. | W7: MINI. | X7: CAD.- JUNIO. | Y7: FEM. | Z7: TOTAL | AA7: TOTAL CUMUL | AC7: CC2
B8: API | C8: ='Tableaux Croisés'!P7 -> 40 | D8: ='Tableaux Croisés'!B7 -> 160 | E8: ='Tableaux Croisés'!I7 -> 49 | F8: ='Tableaux Croisés'!I25 -> 28 | G8: ='Tableaux Croisés'!B25 -> 12 | H8: =SUM(C8:G8) -> 289 | I8: ='Tableaux Croisés'!Q7 -> 17 | J8: ='Tableaux Croisés'!C7 -> 113 | K8: ='Tableaux Croisés'!J7 -> 57 | L8: ='Tableaux Croisés'!J25 -> 6 | M8: ='Tableaux Croisés'!C25 -> 11 | N8: =SUM(I8:M8) -> 204 | O8: ='Tableaux Croisés'!R7 -> 0 | P8: ='Tableaux Croisés'!D7 -> 0 | Q8: ='Tableaux Croisés'!K7 -> 0 | R8: ='Tableaux Croisés'!K25 -> 0 | S8: ='Tableaux Croisés'!D25 -> 0 | T8: =SUM(O8:S8) -> 0 | U8: ='Tableaux Croisés'!S7 -> 0 | V8: ='Tableaux Croisés'!E7 -> 0 | W8: ='Tableaux Croisés'!L7 -> 0 | X8: ='Tableaux Croisés'!L25 -> 0 | Y8: ='Tableaux Croisés'!E25 -> 0 | Z8: =SUM(U8:Y8) -> 0 | AA8: =SUM(H8,N8,T8,Z8) -> 493 | AC8: COS
B9: USP | C9: ='Tableaux Croisés'!P16 -> 20 | D9: ='Tableaux Croisés'!B16 -> 77 | E9: ='Tableaux Croisés'!I16 -> 35 | F9: ='Tableaux Croisés'!I34 -> 37 | G9: ='Tableaux Croisés'!B34 -> 20 | H9: =SUM(C9:G9) -> 189 | I9: ='Tableaux Croisés'!Q16 -> 17 | J9: ='Tableaux Croisés'!C16 -> 54 | K9: ='Tableaux Croisés'!J16 -> 43 | L9: ='Tableaux Croisés'!J34 -> 35 | M9: ='Tableaux Croisés'!C34 -> 18 | N9: =SUM(I9:M9) -> 167 | O9: ='Tableaux Croisés'!R16 -> 0 | P9: ='Tableaux Croisés'!D16 -> 0 | Q9: ='Tableaux Croisés'!K16 -> 0 | R9: ='Tableaux Croisés'!K34 -> 0 | S9: ='Tableaux Croisés'!D34 -> 0 | T9: =SUM(O9:S9) -> 0 | U9: ='Tableaux Croisés'!S16 -> 0 | V9: ='Tableaux Croisés'!E16 -> 0 | W9: ='Tableaux Croisés'!L16 -> 0 | X9: ='Tableaux Croisés'!L34 -> 0 | Y9: ='Tableaux Croisés'!E34 -> 0 | Z9: =SUM(U9:Y9) -> 0 | AA9: =SUM(H9,N9,T9,Z9) -> 356 | AC9: COU
B10: CC2 | C10: ='Tableaux Croisés'!P11 -> 3 | D10: ='Tableaux Croisés'!B11 -> 68 | E10: ='Tableaux Croisés'!I11 -> 72 | F10: ='Tableaux Croisés'!I29 -> 41 | G10: ='Tableaux Croisés'!B29 -> 6 | H10: =SUM(C10:G10) -> 190 | I10: ='Tableaux Croisés'!Q11 -> 0 | J10: ='Tableaux Croisés'!C11 -> 70 | K10: ='Tableaux Croisés'!J11 -> 34 | L10: ='Tableaux Croisés'!J29 -> 48 | M10: ='Tableaux Croisés'!C29 -> 5 | N10: =SUM(I10:M10) -> 157 | O10: ='Tableaux Croisés'!R11 -> 0 | P10: ='Tableaux Croisés'!D11 -> 0 | Q10: ='Tableaux Croisés'!K11 -> 0 | R10: ='Tableaux Croisés'!K29 -> 0 | S10: ='Tableaux Croisés'!D29 -> 0 | T10: =SUM(O10:S10) -> 0 | U10: ='Tableaux Croisés'!S11 -> 0 | V10: ='Tableaux Croisés'!E11 -> 0 | W10: ='Tableaux Croisés'!L11 -> 0 | X10: ='Tableaux Croisés'!L29 -> 0 | Y10: ='Tableaux Croisés'!E29 -> 0 | Z10: =SUM(U10:Y10) -> 0 | AA10: =SUM(H10,N10,T10,Z10) -> 347 | AC10: TTJ-BUC
B11: USBY | C11: ='Tableaux Croisés'!P15 -> 5 | D11: ='Tableaux Croisés'!B15 -> 73 | E11: ='Tableaux Croisés'!I15 -> 28 | F11: ='Tableaux Croisés'!I33 -> 31 | G11: ='Tableaux Croisés'!B35 -> 0 | H11: =SUM(C11:G11) -> 137 | I11: ='Tableaux Croisés'!Q15 -> 1 | J11: ='Tableaux Croisés'!C15 -> 22 | K11: ='Tableaux Croisés'!J15 -> 26 | L11: ='Tableaux Croisés'!J33 -> 19 | M11: ='Tableaux Croisés'!C33 -> 0 | N11: =SUM(I11:M11) -> 68 | O11: ='Tableaux Croisés'!R15 -> 0 | P11: ='Tableaux Croisés'!D15 -> 0 | Q11: ='Tableaux Croisés'!K15 -> 0 | R11: ='Tableaux Croisés'!K33 -> 0 | S11: ='Tableaux Croisés'!D33 -> 0 | T11: =SUM(O11:S11) -> 0 | U11: ='Tableaux Croisés'!S15 -> 0 | V11: ='Tableaux Croisés'!E15 -> 0 | W11: ='Tableaux Croisés'!L15 -> 0 | X11: ='Tableaux Croisés'!L33 -> 0 | Y11: ='Tableaux Croisés'!E33 -> 0 | Z11: =SUM(U11:Y11) -> 0 | AA11: =SUM(H11,N11,T11,Z11) -> 205 | AC11: USBY
B12: CAO | C12: ='Tableaux Croisés'!P10 -> 9 | D12: ='Tableaux Croisés'!B10 -> 24 | E12: ='Tableaux Croisés'!I10 -> 43 | F12: ='Tableaux Croisés'!I28 -> 23 | G12: ='Tableaux Croisés'!B28 -> 2 | H12: =SUM(C12:G12) -> 101 | I12: ='Tableaux Croisés'!Q10 -> 9 | J12: ='Tableaux Croisés'!C10 -> 35 | K12: ='Tableaux Croisés'!J10 -> 15 | L12: ='Tableaux Croisés'!J28 -> 21 | M12: ='Tableaux Croisés'!C28 -> 0 | N12: =SUM(I12:M12) -> 80 | O12: ='Tableaux Croisés'!R10 -> 0 | P12: ='Tableaux Croisés'!D10 -> 0 | Q12: ='Tableaux Croisés'!K10 -> 0 | R12: ='Tableaux Croisés'!K28 -> 0 | S12: ='Tableaux Croisés'!D28 -> 0 | T12: =SUM(O12:S12) -> 0 | U12: ='Tableaux Croisés'!S10 -> 0 | V12: ='Tableaux Croisés'!E10 -> 0 | W12: ='Tableaux Croisés'!L10 -> 0 | X12: ='Tableaux Croisés'!L28 -> 0 | Y12: ='Tableaux Croisés'!E28 -> 0 | Z12: =SUM(U12:Y12) -> 0 | AA12: =SUM(H12,N12,T12,Z12) -> 181 | AC12: USP
B13: TTJ-BUC | C13: ='Tableaux Croisés'!P14 -> 25 | D13: ='Tableaux Croisés'!B14 -> 26 | E13: ='Tableaux Croisés'!I14 -> 31 | F13: ='Tableaux Croisés'!I32 -> 11 | G13: ='Tableaux Croisés'!B32 -> 0 | H13: =SUM(C13:G13) -> 93 | I13: ='Tableaux Croisés'!Q14 -> 7 | J13: ='Tableaux Croisés'!C14 -> 17 | K13: ='Tableaux Croisés'!J14 -> 13 | L13: ='Tableaux Croisés'!J32 -> 0 | M13: ='Tableaux Croisés'!C32 -> 0 | N13: =SUM(I13:M13) -> 37 | O13: ='Tableaux Croisés'!R14 -> 0 | P13: ='Tableaux Croisés'!D14 -> 0 | Q13: ='Tableaux Croisés'!K14 -> 0 | R13: ='Tableaux Croisés'!K32 -> 0 | S13: ='Tableaux Croisés'!D32 -> 0 | T13: =SUM(O13:S13) -> 0 | U13: ='Tableaux Croisés'!S14 -> 0 | V13: ='Tableaux Croisés'!E14 -> 0 | W13: ='Tableaux Croisés'!L14 -> 0 | X13: ='Tableaux Croisés'!L32 -> 0 | Y13: ='Tableaux Croisés'!E32 -> 0 | Z13: =SUM(U13:Y13) -> 0 | AA13: =SUM(H13,N13,T13,Z13) -> 130 | AC13: VAU
B14: COU | C14: ='Tableaux Croisés'!P13 -> 17 | D14: ='Tableaux Croisés'!B13 -> 35 | E14: ='Tableaux Croisés'!I13 -> 1 | F14: ='Tableaux Croisés'!I31 -> 0 | G14: ='Tableaux Croisés'!B31 -> 0 | H14: =SUM(C14:G14) -> 53 | I14: ='Tableaux Croisés'!Q13 -> 5 | J14: ='Tableaux Croisés'!C13 -> 37 | K14: ='Tableaux Croisés'!J13 -> 1 | L14: ='Tableaux Croisés'!J31 -> 6 | M14: ='Tableaux Croisés'!C31 -> 0 | N14: =SUM(I14:M14) -> 49 | O14: ='Tableaux Croisés'!R13 -> 0 | P14: ='Tableaux Croisés'!D13 -> 0 | Q14: ='Tableaux Croisés'!K13 -> 0 | R14: ='Tableaux Croisés'!K31 -> 0 | S14: ='Tableaux Croisés'!D31 -> 0 | T14: =SUM(O14:S14) -> 0 | U14: ='Tableaux Croisés'!S13 -> 0 | V14: ='Tableaux Croisés'!E13 -> 0 | W14: ='Tableaux Croisés'!L13 -> 0 | X14: ='Tableaux Croisés'!L31 -> 0 | Y14: ='Tableaux Croisés'!E31 -> 0 | Z14: =SUM(U14:Y14) -> 0 | AA14: =SUM(H14,N14,T14,Z14) -> 102
B15: VAU | C15: ='Tableaux Croisés'!P17 -> 0 | D15: ='Tableaux Croisés'!B17 -> 22 | E15: ='Tableaux Croisés'!I17 -> 27 | F15: ='Tableaux Croisés'!I35 -> 22 | G15: ='Tableaux Croisés'!B35 -> 0 | H15: =SUM(C15:G15) -> 71 | I15: ='Tableaux Croisés'!Q17 -> 0 | J15: ='Tableaux Croisés'!C1 -> 0 | K15: ='Tableaux Croisés'!J17 -> 10 | L15: ='Tableaux Croisés'!J35 -> 18 | M15: ='Tableaux Croisés'!C35 -> 0 | N15: =SUM(I15:M15) -> 28 | O15: ='Tableaux Croisés'!R17 -> 0 | P15: ='Tableaux Croisés'!D17 -> 0 | Q15: ='Tableaux Croisés'!K17 -> 0 | R15: ='Tableaux Croisés'!K35 -> 0 | S15: ='Tableaux Croisés'!D35 -> 0 | T15: =SUM(O15:S15) -> 0 | U15: ='Tableaux Croisés'!S17 -> 0 | V15: ='Tableaux Croisés'!E17 -> 0 | W15: ='Tableaux Croisés'!L17 -> 0 | X15: ='Tableaux Croisés'!L35 -> 0 | Y15: ='Tableaux Croisés'!E35 -> 0 | Z15: =SUM(U15:Y15) -> 0 | AA15: =SUM(H15,N15,T15,Z15) -> 99
B16: ASV | C16: ='Tableaux Croisés'!P9 -> 16 | D16: ='Tableaux Croisés'!B9 -> 29 | E16: ='Tableaux Croisés'!I9 -> 14 | F16: ='Tableaux Croisés'!I27 -> 4 | G16: ='Tableaux Croisés'!B27 -> 5 | H16: =SUM(C16:G16) -> 68 | I16: ='Tableaux Croisés'!Q9 -> 8 | J16: ='Tableaux Croisés'!C9 -> 7 | K16: ='Tableaux Croisés'!J9 -> 6 | L16: ='Tableaux Croisés'!J27 -> 0 | M16: ='Tableaux Croisés'!C27 -> 3 | N16: =SUM(I16:M16) -> 24 | O16: ='Tableaux Croisés'!R9 -> 0 | P16: ='Tableaux Croisés'!D9 -> 0 | Q16: ='Tableaux Croisés'!K9 -> 0 | R16: ='Tableaux Croisés'!K27 -> 0 | S16: ='Tableaux Croisés'!D27 -> 0 | T16: =SUM(O16:S16) -> 0 | U16: ='Tableaux Croisés'!S9 -> 0 | V16: ='Tableaux Croisés'!E9 -> 0 | W16: ='Tableaux Croisés'!L9 -> 0 | X16: ='Tableaux Croisés'!L27 -> 0 | Y16: ='Tableaux Croisés'!E27 -> 0 | Z16: =SUM(U16:Y16) -> 0 | AA16: =SUM(H16,N16,T16,Z16) -> 92
B17: ASM | C17: ='Tableaux Croisés'!P8 -> 0 | D17: ='Tableaux Croisés'!B8 -> 0 | E17: ='Tableaux Croisés'!I8 -> 0 | F17: ='Tableaux Croisés'!I26 -> 18 | G17: ='Tableaux Croisés'!B26 -> 0 | H17: =SUM(C17:G17) -> 18 | I17: ='Tableaux Croisés'!Q8 -> 0 | J17: ='Tableaux Croisés'!C8 -> 0 | K17: ='Tableaux Croisés'!J8 -> 2 | L17: ='Tableaux Croisés'!J26 -> 12 | M17: ='Tableaux Croisés'!C26 -> 0 | N17: =SUM(I17:M17) -> 14 | O17: ='Tableaux Croisés'!R8 -> 0 | P17: ='Tableaux Croisés'!D8 -> 0 | Q17: ='Tableaux Croisés'!K8 -> 0 | R17: ='Tableaux Croisés'!K26 -> 0 | S17: ='Tableaux Croisés'!D26 -> 0 | T17: =SUM(O17:S17) -> 0 | U17: ='Tableaux Croisés'!S8 -> 0 | V17: ='Tableaux Croisés'!E8 -> 0 | W17: ='Tableaux Croisés'!L8 -> 0 | X17: ='Tableaux Croisés'!L26 -> 0 | Y17: ='Tableaux Croisés'!E26 -> 0 | Z17: =SUM(U17:Y17) -> 0 | AA17: =SUM(H17,N17,T17,Z17) -> 32
B18: COS | C18: ='Tableaux Croisés'!P12 -> 1 | D18: ='Tableaux Croisés'!B12 -> 8 | E18: ='Tableaux Croisés'!I12 -> 1 | F18: ='Tableaux Croisés'!I30 -> 0 | G18: ='Tableaux Croisés'!B30 -> 3 | H18: =SUM(C18:G18) -> 13 | I18: ='Tableaux Croisés'!Q12 -> 0 | J18: ='Tableaux Croisés'!C12 -> 0 | K18: ='Tableaux Croisés'!J12 -> 0 | L18: ='Tableaux Croisés'!J30 -> 0 | M18: ='Tableaux Croisés'!C30 -> 0 | N18: =SUM(I18:M18) -> 0 | O18: ='Tableaux Croisés'!R12 -> 0 | P18: ='Tableaux Croisés'!D12 -> 0 | Q18: ='Tableaux Croisés'!K12 -> 0 | R18: ='Tableaux Croisés'!K30 -> 0 | S18: ='Tableaux Croisés'!D30 -> 0 | T18: =SUM(O18:S18) -> 0 | U18: ='Tableaux Croisés'!S12 -> 0 | V18: ='Tableaux Croisés'!E12 -> 0 | W18: ='Tableaux Croisés'!L12 -> 0 | X18: ='Tableaux Croisés'!L30 -> 0 | Y18: ='Tableaux Croisés'!E30 -> 0 | Z18: =SUM(U18:Y18) -> 0 | AA18: =SUM(H18,N18,T18,Z18) -> 13
B22: PARTICIPANTS
O23: Nombre de Valeur
D24: 1er Tour | F24: 2nd Tour | H24: 3ème Tour | J24: 4ème Tour | L24: Total | O24: Étiquettes de lignes | P24: Pr. T1 | Q24: Pr. T2 | R24: Pr. T3 | S24: Pr. T4 | T24: Total général
O25: API | P25: 45 | Q25: 33 | T25: 78
B26: Poussins | E26: =Poussins!H117 -> 30 | G26: =Poussins!J117 -> 16 | I26: =Poussins!L117 -> 23 | K26: =Poussins!N117 -> 0 | L26: =SUM(E26:K26) -> 69 | O26: ASM | P26: 5 | Q26: 6 | T26: 11
B27: Benjamins | E27: =Benjamins!H219 -> 86 | G27: =Benjamins!J219 -> 62 | I27: =Benjamins!L219 -> 0 | K27: =Benjamins!N219 -> 0 | L27: =SUM(E27:K27) -> 148 | O27: ASV | P27: 14 | Q27: 5 | T27: 19
B28: Minimes | E28: =Minimes!H175 -> 58 | G28: =Minimes!J175 -> 39 | I28: =Minimes!L175 -> 32 | K28: =Minimes!N175 -> 0 | L28: =SUM(E28:K28) -> 129 | O28: CAO | P28: 18 | Q28: 13 | T28: 31
B29: Cadets-Juniors | E29: ='Cadets-Juniors'!H136 -> 39 | G29: ='Cadets-Juniors'!J136 -> 31 | I29: ='Cadets-Juniors'!L136 -> 24 | K29: ='Cadets-Juniors'!N136 -> 0 | L29: =SUM(E29:K29) -> 94 | O29: CC2 | P29: 39 | Q29: 26 | T29: 65
B30: Féminines | E30: =Feminines!H86 -> 9 | G30: =Feminines!J86 -> 7 | I30: =Feminines!L86 -> 10 | K30: =Feminines!N86 -> 0 | L30: =SUM(E30:K30) -> 26 | O30: COS | P30: 4 | T30: 4
B31: TOTAL | E31: =SUM(E26:E30) -> 222 | G31: =SUM(G26:G30) -> 155 | I31: =SUM(I26:I30) -> 89 | K31: =SUM(K26:K30) -> 0 | L31: =SUM(L26:L30) -> 466 | O31: COU | P31: 16 | Q31: 15 | T31: 31
O32: TTJ-BUC | P32: 18 | Q32: 9 | T32: 27
O33: USBY | P33: 22 | Q33: 12 | T33: 34
O34: USP | P34: 25 | Q34: 25 | T34: 50
O35: VAU | P35: 14 | Q35: 11 | T35: 25
O36: Total général | P36: 220 | Q36: 155 | T36: 375

Sheet Dossard
A1: Dossard | B1: NOM | C1: PRENOM | D1: Sexe | E1: Naiss | F1: Club | G1: Class.
A2: 1069 | B2: ABBADI | C2: Neil | D2: M | E2: 42911 | F2: USP | G2: 500
A3: 2185 | B3: ACOLATSE | C3: Matthias | D3: M | F3: CC2
A4: 3140 | B4: ACOLATSE | C4: Timothe | D4: M | F4: CC2
A5: 3099 | B5: ACREMANN | C5: Gabriel | D5: M | E5: 41307 | F5: USP | G5: 574
A6: 3080 | B6: ADOUE | C6: Theo | D6: M | E6: 41973 | F6: VAU | G6: 500
A7: 3041 | B7: ALAUME | C7: Louise | D7: F | E7: 41694 | F7: CAO | G7: 500
A8: 4001 | B8: ALCIDE | C8: Ethan | D8: M | E8: 41032 | F8: USP | G8: 500
A9: 1070 | B9: ALINE | C9: Calie | D9: F | E9: 43191 | F9: API | G9: 500
A10: 1071 | B10: ALINE | C10: Milan | D10: M | E10: 44075 | F10: API | G10: 500
A11: 3073 | B11: ALVES | C11: Liam | D11: M | E11: 41339 | F11: COU | G11: 500
A12: 1063 | B12: AMMAR KHODJA | C12: Yanis | D12: M | E12: 42765 | F12: COU | G12: 500
A13: 1072 | B13: AMOURETTE | C13: Leo | D13: M | E13: 42775 | F13: API | G13: 500
A14: 3096 | B14: ANDRIEUX | C14: Laora | D14: F | E14: 41620 | F14: USP | G14: 575
A15: 4002 | B15: ANDRIEUX | C15: Leelouane | D15: F | E15: 40917 | F15: USP | G15: 500
A16: 1068 | B16: ANDRIEUX | C16: Timeo | D16: M | E16: 43264 | F16: USP | G16: 508
... A18: 2085 | B18: ASLAN | C18: Merwan | D18: M | E18: 42192 | F18: COU | G18: 500
A19: 2012 | B19: AUBERT | C19: Lucie | D19: F | E19: 42666 | F19: TTJ-BUC | G19: 500
A20: 1073 | B20: AUDISIO | C20: Alexandre | D20: M | E20: 43245 | F20: API | G20: 500
A21: 2142 | B21: AUDISIO | C21: Julian | D21: M | E21: 42508 | F21: API | G21: 500
A22: 3050 | B22: AYRAULT | C22: Elio | D22: M | E22: 41607 | F22: CC2 | G22: 500
A23: 1028 | B23: AYRAULT | C23: Matheis | D23: M | E23: 43182 | F23: CC2 | G23: 500
A24: 3036 | B24: AZAMBOURG | C24: Hadrien | D24: M | E24: 41736 | F24: CC2 | G24: 500
A25: 2043 | B25: BADUEL | C25: Edgar | D25: M | E25: 42411 | F25: CC2 | G25: 500
A26: 2132 | B26: BAJARD | C26: Timeo | D26: M | E26: 42334 | F26: USP | G26: 500
A27: 4003 | B27: BALIGAND | C27: Corentin | D27: M | E27: 40861 | F27: CAO | G27: 647
A28: 2059 | B28: BALOCHE FERNOUX | C28: Liam | D28: M | E28: 42335 | F28: CC2 | G28: 500
A29: 1035 | B29: BAMBA | C29: Mohamed-Adams | D29: M | E29: 43110 | F29: COU | G29: 500
A30: 1023 | B30: BANU | C30: Luca | D30: M | E30: 43232 | F30: CC2 | G30: 500
A31: 3076 | B31: BARBIER | C31: Gabriel | D31: M | E31: 41304 | F31: CC2 | G31: 500
A32: 2036 | B32: BASSET | C32: Theo | D32: M | E32: 42469 | F32: CAO | G32: 500
A33: 2183 | B33: BASSIR | C33: Ryan | D33: M | E33: 42469 | F33: USP | G33: 500
A34: 4004 | B34: BAUDOU | C34: Ilyan | D34: M | E34: 40909 | F34: ASM | G34: 500
A35: 2102 | B35: BAUDRY JAMINET | C35: Matteo | D35: M | E35: 42066 | F35: CC2 | G35: 500
A36: 1004 | B36: BEAUJOT | C36: Jean | D36: M | E36: 43818 | F36: CC2 | G36: 500
A37: 4005 | B37: BEAUVINEAU | C37: Ethan | D37: M | E37: 41002 | F37: USBY | G37: 500
A38: 2143 | B38: BELHOUARI | C38: Sami | D38: M | E38: 42407 | F38: API | G38: 500
A39: 2100 | B39: BELLENGER | C39: Nathan | D39: M | E39: 42072 | F39: ASV | G39: 500
A40: 4006 | B40: BELLIL NASCIET | C40: Nora | D40: F | E40: 41002 | F40: API | G40: 500
A41: 2113 | B41: BENAZERAF | C41: Ely | D41: M | E41: 42617 | F41: VAU | G41: 500
...
